Workbook

Sheet Leyenda
A1: Grupo de anuncios Pinza V2 — plan de cambios y seguimiento
A2: Producto: Soporte Móvil para Coche con Pinza Ajustable 360° para Salpicadero/Parasol/Espejo Retrovisor, A… | ASIN B0DCZS1NR6 | SKU O8-5W7J-DSK1 | Creado 25/09/2026
A4: PARÁMETROS
A5: ACOS objetivo | B5: 0.35 | C5: Confirmado por Juan (25/09/2026).
A6: Ticket medio (€/venta) | B6: 11.24 | C6: Ventas ÷ compras del soporte de pinza en los exports de Amazon Ads (35 compras).
A7: Presupuesto mensual total | B7: 100 | C7: CLAUDE.md: límite duro de 100 €/mes.
A8: % del presupuesto para pruebas | B8: 0.5 | C8: Pedido por Juan (26/09/2026): 50% para la campaña de pruebas (ASIN de competencia + categoría).
A9: Presupuesto diario campaña principal | B9: =ROUND(B7*(1-B8)/30,2) -> 1.67 | C9: Resto del presupuesto ÷ 30 días. En Amazon el presupuesto es por campaña.
A10: Días entre revisiones de puja | B10: 3 | C10: Pedido por Juan.
A11: Rango de puja sobre la original | B11: 0.5 | C11: Pedido por Juan: ±50% de la puja original.
A12: Stop-loss: clics sin ventas | B12: 15 | C12: Propuesto; pendiente de confirmar por Juan.
A13: Clics mínimos para evaluar un cambio | B13: 10 | C13: Igual que CLAUDE.md: con menos clics es ruido.
A14: Presupuesto diario campaña de pruebas | B14: =ROUND(B7*B8/30,2) -> 1.67 | C14: 50% de 100 € ÷ 30 días.
A15: Días para evaluar un cambio | B15: 7 | C15: Sponsored Products atribuye ventas hasta 7 días después del clic: antes, los datos están incompletos.
A17: CÓMO USAR ESTE EXCEL
A18: 1. Aplica en Amazon Ads los tickets 'Pendiente de aplicar' en orden (grupo principal y keywords, cartera, campaña de pruebas y sus productos, negativas). Al aplicar cada uno, pon la fecha en Tickets → 'Fecha aplicado' y cambia el estado a 'Aplicado'.
A19: 2. Cada 3 días: en Amazon Ads, pestaña Segmentación de este grupo, exporta con rango DESDE EL DÍA DE CREACIÓN HASTA HOY (acumulado). Copia una fila por keyword en 'Seguimiento' (fecha + Puja, Impresiones, Clics, Coste, Compras, Ventas). Todo lo demás se calcula solo.
A20: 3. 'Segmentación' muestra el estado actual de cada keyword como en Amazon, con la acción sugerida y los avisos de stop-loss.
A21: 4. Cuando cambies una puja o pauses algo: añade un ticket nuevo en 'Tickets' (hay filas preparadas). En 'Base' copia los Clics/Coste/Compras/Ventas acumulados que muestra 'Segmentación' en ese momento: así el ticket mide SOLO lo que pasa después de ese cambio.
A22: 5. Cada ticket se evalúa solo: 'Veredicto' dice Mejora/Empeora cuando hay al menos 10 clics nuevos. No lo des por bueno antes de 'Revisar a partir de' (7 días): las ventas llegan hasta 7 días después del clic.
A23: 6. Cada 2 semanas: descarga el informe de TÉRMINOS DE BÚSQUEDA (Amazon solo guarda 65 días). Términos con ≥10 clics y 0 ventas → negativa exacta (ticket nuevo). Términos con ventas y ACOS ≤ 35% que no sean keyword → keyword nueva en Exacta.
A24: 7. A las 2 semanas: mira el informe de UBICACIÓN. Si 'Parte superior de la búsqueda' tiene mejor ACOS que el resto, súbele el ajuste (+10-25%) con un ticket; si es peor, déjalo en 0%.
A26: COLORES
A27: Ejemplo | B27: Celda para rellenar / editar (texto azul, fondo amarillo)
A28: Ejemplo | B28: Keyword histórica: ya demostró que vende
A29: Ejemplo | B29: Keyword especial propuesta por la IA (no es prueba: mismas reglas que las históricas)
A30: Ejemplo | B30: Campaña de pruebas: segmentación por producto (ASIN) o categoría
A31: Ejemplo | B31: Texto verde: dato que viene de otra hoja
A33: AVISOS
A34: • Las campañas antiguas siguen en pausa. Si alguna se reactiva, sus keywords competirían con las de este grupo en la misma subasta (tú contra ti). Mantenlas en pausa o pausa ahí estas mismas keywords.
A35: • El presupuesto diario en Amazon es por CAMPAÑA: si este grupo va en una campaña con otros grupos, el presupuesto lo comparten.
A36: • Los anuncios solo salen si tienes la OFERTA DESTACADA (Buy Box) y stock. Si un día hay 0 impresiones, mira eso antes de tocar pujas.
A37: • Los ASIN de competencia se sacaron de una búsqueda web: comprueba en amazon.es que siguen vendiéndose y que son más caros o con peores reseñas que el tuyo antes de aplicarlos.
A38: • Las 5 keywords especiales no tienen datos propios: su puja sale del modelo (keyword_ml.py) y no del histórico. Por eso se revisan con más cuidado las primeras semanas.

Sheet Grupo de anuncios
A1: Configuración del grupo de anuncios (tal cual se rellena en Amazon Ads)
A3: Campo | B3: Valor
A4: Campaña | B4: Soporte móvil pinza (ID A0335903WCRWL9CYXAOF)
A5: Tipo de campaña | B5: Sponsored Products — Segmentación manual
A6: Nombre del grupo de anuncios | B6: Pinza - Principal V2
A7: Estado | B7: Activado
A8: Puja predeterminada del grupo (EUR) | B8: 0.4
A9: Estrategia de puja de la campaña | B9: Pujas dinámicas: solo reducir
A10: Presupuesto diario de la campaña (EUR) | B10: =Leyenda!B9 -> 1.67
A11: Anuncio: ASIN | B11: B0DCZS1NR6
A12: Anuncio: SKU | B12: O8-5W7J-DSK1
A13: Anuncio: Nombre | B13: Soporte Móvil para Coche con Pinza Ajustable 360° para Salpicadero/Parasol/Espejo Retrovisor, Antideslizante y Estable | Compatible con iPhone, Samsung, Xiaomi y Más
A14: Segmentación | B14: Palabras clave (10) — ver hoja 'Segmentación'
A15: Ticket de creación | B15: T-001
A16: Cartera (portfolio) | B16: FreshFinder - 100 €/mes: límite de presupuesto MENSUAL recurrente de 100 €, con esta campaña y la de pruebas dentro
A17: Ajuste por ubicación: parte superior de la búsqueda | B17: 0% al empezar; revisar el informe de ubicación a las 2 semanas
A18: Ajuste por ubicación: resto de la búsqueda | B18: 0%
A19: Ajuste por ubicación: páginas de producto | B19: 0%
A21: CAMPAÑA DE PRUEBAS
A22: Campaña | B22: Pinza - Pruebas (nueva)
A23: Tipo de campaña | B23: Sponsored Products — Segmentación manual por producto
A24: Presupuesto diario (EUR) | B24: =Leyenda!B14 -> 1.67
A25: Estrategia de puja | B25: Pujas dinámicas: solo reducir
A26: Cartera | B26: FreshFinder - 100 €/mes
A27: Grupo de anuncios | B27: Pruebas - Competencia
A28: Puja predeterminada (EUR) | B28: 0.3
A29: Anuncio | B29: B0DCZS1NR6 (O8-5W7J-DSK1)
A30: Segmentación | B30: 4 ASIN de competencia + 1 categoría con filtros — ver 'Segmentación' (filas naranjas)
A31: Producto negativo | B31: asin="B0DCZS1NR6" (tu propia ficha)
A32: Tickets | B32: T-012 (cartera), T-013 (campaña) … ver 'Tickets'

Sheet Segmentación
A1: Segmentación — grupo 'Pinza - Principal V2' (verde/azul) y campaña 'Pinza - Pruebas' (naranja). Mismas columnas que el export de Amazon Ads; se actualiza desde 'Seguimiento'.
A3: Estado | B3: Palabra clave | C3: Tipo de coincidencia objetivo | D3: Puja (EUR) | E3: Impresiones | F3: Clics | G3: CTR | H3: Coste total (EUR) | I3: CPC (EUR) | J3: Compras | K3: Ventas (EUR) | L3: ACOS | M3: ROAS | N3: Origen | O3: Puja original (EUR) | P3: Puja mín. -50% (EUR) | Q3: Puja máx. +50% (EUR) | R3: Puja máx. rentable (EUR) | S3: Ticket | T3: Última foto | U3: Stop-loss | V3: Acción sugerida | W3: Clave
A4: =IFERROR(INDEX(Seguimiento!$D:$D,MATCH(W4&"#"&_xlfn.MAXIFS(Seguimiento!$A:$A,Seguimiento!$Q:$Q,W4),Seguimiento!$R:$R,0)),"Activado") -> Activado | B4: soporte móvil para coche con pinza | C4: Frase | D4: =IFERROR(IF(_xlfn.MAXIFS(Seguimiento!$A:$A,Seguimiento!$Q:$Q,W4)=0,O4,SUMIFS(Seguimiento!$F:$F,Seguimiento!$Q:$Q,W4,Seguimiento!$A:$A,_xlfn.MAXIFS(Seguimiento!$A:$A,Seguimiento!$Q:$Q,W4))),O4) -> 0.78 | E4: =IFERROR(SUMIFS(Seguimiento!$G:$G,Seguimiento!$Q:$Q,W4,Seguimiento!$A:$A,_xlfn.MAXIFS(Seguimiento!$A:$A,Seguimiento!$Q:$Q,W4)),0) -> 0 | F4: =IFERROR(SUMIFS(Seguimiento!$H:$H,Seguimiento!$Q:$Q,W4,Seguimiento!$A:$A,_xlfn.MAXIFS(Seguimiento!$A:$A,Seguimiento!$Q:$Q,W4)),0) -> 0 | G4: =IFERROR(F4/E4,0) -> 0 | H4: =IFERROR(SUMIFS(Seguimiento!$I:$I,Seguimiento!$Q:$Q,W4,Seguimiento!$A:$A,_xlfn.MAXIFS(Seguimiento!$A:$A,Seguimiento!$Q:$Q,W4)),0) -> 0 | I4: =IFERROR(H4/F4,0) -> 0 | J4: =IFERROR(SUMIFS(Seguimiento!$J:$J,Seguimiento!$Q:$Q,W4,Seguimiento!$A:$A,_xlfn.MAXIFS(Seguimiento!$A:$A,Seguimiento!$Q:$Q,W4)),0) -> 0 | K4: =IFERROR(SUMIFS(Seguimiento!$K:$K,Seguimiento!$Q:$Q,W4,Seguimiento!$A:$A,_xlfn.MAXIFS(Seguimiento!$A:$A,Seguimiento!$Q:$Q,W4)),0) -> 0 | L4: =IFERROR(H4/K4,0) -> 0 | M4: =IFERROR(K4/H4,0) -> 0 | N4: Histórica | O4: 0.78 | P4: =ROUND(O4*(1-Leyenda!$B$11),2) -> 0.39 | Q4: =ROUND(O4*(1+Leyenda!$B$11),2) -> 1.17 | R4: 0.85 | S4: T-002 | T4: =IFERROR(IF(_xlfn.MAXIFS(Seguimiento!$A:$A,Seguimiento!$Q:$Q,W4)=0,"",_xlfn.MAXIFS(Seguimiento!$A:$A,Seguimiento!$Q:$Q,W4)),"") -> 46290 | U4: =IF(AND(F4>=Leyenda!$B$12,J4=0),"PAUSAR (≥15 clics sin venta)",IF(AND(D4<=P4,F4>=20,L4>0.5),"PAUSAR (puja mínima y ACOS>50%)","")) | V4: =IF(LEFT(U4,6)="PAUSAR","Pausar y crear ticket",IF(F4<Leyenda!$B$13,"Esperar (menos de 10 clics)",IF(J4=0,"Sin ventas aún: vigilar",IF(L4<0.3,"Subir 10-25% (máx. "&TEXT(MIN(Q4,R4),"0.00")&" €)",IF(L4<=Leyenda!$B$5,"En objetivo: no tocar",IF(L4<=0.5,"Bajar 10-25% (mín. "&TEXT(P4,"0.00")&" €)","Bajar 25-50% (mín. "&TEXT(P4,"0.00")&" €)")))))) -> Esperar (menos de 10 clics) | W4: =B4&" | "&C4 -> soporte móvil para coche con pinza | Frase
A5: =IFERROR(INDEX(Seguimiento!$D:$D,MATCH(W5&"#"&_xlfn.MAXIFS(Seguimiento!$A:$A,Seguimiento!$Q:$Q,W5),Seguimiento!$R:$R,0)),"Activado") -> Activado | B5: soporte móvil para coche de pinza para salpicadero | C5: Amplia | D5: =IFERROR(IF(_xlfn.MAXIFS(Seguimiento!$A:$A,Seguimiento!$Q:$Q,W5)=0,O5,SUMIFS(Seguimiento!$F:$F,Seguimiento!$Q:$Q,W5,Seguimiento!$A:$A,_xlfn.MAXIFS(Seguimiento!$A:$A,Seguimiento!$Q:$Q,W5))),O5) -> 0.3 | E5: =IFERROR(SUMIFS(Seguimiento!$G:$G,Seguimiento!$Q:$Q,W5,Seguimiento!$A:$A,_xlfn.MAXIFS(Seguimiento!$A:$A,Seguimiento!$Q:$Q,W5)),0) -> 0 | F5: =IFERROR(SUMIFS(Seguimiento!$H:$H,Seguimiento!$Q:$Q,W5,Seguimiento!$A:$A,_xlfn.MAXIFS(Seguimiento!$A:$A,Seguimiento!$Q:$Q,W5)),0) -> 0 | G5: =IFERROR(F5/E5,0) -> 0 | H5: =IFERROR(SUMIFS(Seguimiento!$I:$I,Seguimiento!$Q:$Q,W5,Seguimiento!$A:$A,_xlfn.MAXIFS(Seguimiento!$A:$A,Seguimiento!$Q:$Q,W5)),0) -> 0 | I5: =IFERROR(H5/F5,0) -> 0 | J5: =IFERROR(SUMIFS(Seguimiento!$J:$J,Seguimiento!$Q:$Q,W5,Seguimiento!$A:$A,_xlfn.MAXIFS(Seguimiento!$A:$A,Seguimiento!$Q:$Q,W5)),0) -> 0 | K5: =IFERROR(SUMIFS(Seguimiento!$K:$K,Seguimiento!$Q:$Q,W5,Seguimiento!$A:$A,_xlfn.MAXIFS(Seguimiento!$A:$A,Seguimiento!$Q:$Q,W5)),0) -> 0 | L5: =IFERROR(H5/K5,0) -> 0 | M5: =IFERROR(K5/H5,0) -> 0 | N5: Histórica | O5: 0.3 | P5: =ROUND(O5*(1-Leyenda!$B$11),2) -> 0.15 | Q5: =ROUND(O5*(1+Leyenda!$B$11),2) -> 0.45 | R5: 0.4 | S5: T-003 | T5: =IFERROR(IF(_xlfn.MAXIFS(Seguimiento!$A:$A,Seguimiento!$Q:$Q,W5)=0,"",_xlfn.MAXIFS(Seguimiento!$A:$A,Seguimiento!$Q:$Q,W5)),"") -> 46290 | U5: =IF(AND(F5>=Leyenda!$B$12,J5=0),"PAUSAR (≥15 clics sin venta)",IF(AND(D5<=P5,F5>=20,L5>0.5),"PAUSAR (puja mínima y ACOS>50%)","")) | V5: =IF(LEFT(U5,6)="PAUSAR","Pausar y crear ticket",IF(F5<Leyenda!$B$13,"Esperar (menos de 10 clics)",IF(J5=0,"Sin ventas aún: vigilar",IF(L5<0.3,"Subir 10-25% (máx. "&TEXT(MIN(Q5,R5),"0.00")&" €)",IF(L5<=Leyenda!$B$5,"En objetivo: no tocar",IF(L5<=0.5,"Bajar 10-25% (mín. "&TEXT(P5,"0.00")&" €)","Bajar 25-50% (mín. "&TEXT(P5,"0.00")&" €)")))))) -> Esperar (menos de 10 clics) | W5: =B5&" | "&C5 -> soporte móvil para coche de pinza para salpicadero | Amplia
A6: =IFERROR(INDEX(Seguimiento!$D:$D,MATCH(W6&"#"&_xlfn.MAXIFS(Seguimiento!$A:$A,Seguimiento!$Q:$Q,W6),Seguimiento!$R:$R,0)),"Activado") -> Activado | B6: soporte móvil para coche de pinza | C6: Exacta | D6: =IFERROR(IF(_xlfn.MAXIFS(Seguimiento!$A:$A,Seguimiento!$Q:$Q,W6)=0,O6,SUMIFS(Seguimiento!$F:$F,Seguimiento!$Q:$Q,W6,Seguimiento!$A:$A,_xlfn.MAXIFS(Seguimiento!$A:$A,Seguimiento!$Q:$Q,W6))),O6) -> 0.51 | E6: =IFERROR(SUMIFS(Seguimiento!$G:$G,Seguimiento!$Q:$Q,W6,Seguimiento!$A:$A,_xlfn.MAXIFS(Seguimiento!$A:$A,Seguimiento!$Q:$Q,W6)),0) -> 0 | F6: =IFERROR(SUMIFS(Seguimiento!$H:$H,Seguimiento!$Q:$Q,W6,Seguimiento!$A:$A,_xlfn.MAXIFS(Seguimiento!$A:$A,Seguimiento!$Q:$Q,W6)),0) -> 0 | G6: =IFERROR(F6/E6,0) -> 0 | H6: =IFERROR(SUMIFS(Seguimiento!$I:$I,Seguimiento!$Q:$Q,W6,Seguimiento!$A:$A,_xlfn.MAXIFS(Seguimiento!$A:$A,Seguimiento!$Q:$Q,W6)),0) -> 0 | I6: =IFERROR(H6/F6,0) -> 0 | J6: =IFERROR(SUMIFS(Seguimiento!$J:$J,Seguimiento!$Q:$Q,W6,Seguimiento!$A:$A,_xlfn.MAXIFS(Seguimiento!$A:$A,Seguimiento!$Q:$Q,W6)),0) -> 0 | K6: =IFERROR(SUMIFS(Seguimiento!$K:$K,Seguimiento!$Q:$Q,W6,Seguimiento!$A:$A,_xlfn.MAXIFS(Seguimiento!$A:$A,Seguimiento!$Q:$Q,W6)),0) -> 0 | L6: =IFERROR(H6/K6,0) -> 0 | M6: =IFERROR(K6/H6,0) -> 0 | N6: Histórica | O6: 0.51 | P6: =ROUND(O6*(1-Leyenda!$B$11),2) -> 0.26 | Q6: =ROUND(O6*(1+Leyenda!$B$11),2) -> 0.77 | R6: 0.6 | S6: T-004 | T6: =IFERROR(IF(_xlfn.MAXIFS(Seguimiento!$A:$A,Seguimiento!$Q:$Q,W6)=0,"",_xlfn.MAXIFS(Seguimiento!$A:$A,Seguimiento!$Q:$Q,W6)),"") -> 46290 | U6: =IF(AND(F6>=Leyenda!$B$12,J6=0),"PAUSAR (≥15 clics sin venta)",IF(AND(D6<=P6,F6>=20,L6>0.5),"PAUSAR (puja mínima y ACOS>50%)","")) | V6: =IF(LEFT(U6,6)="PAUSAR","Pausar y crear ticket",IF(F6<Leyenda!$B$13,"Esperar (menos de 10 clics)",IF(J6=0,"Sin ventas aún: vigilar",IF(L6<0.3,"Subir 10-25% (máx. "&TEXT(MIN(Q6,R6),"0.00")&" €)",IF(L6<=Leyenda!$B$5,"En objetivo: no tocar",IF(L6<=0.5,"Bajar 10-25% (mín. "&TEXT(P6,"0.00")&" €)","Bajar 25-50% (mín. "&TEXT(P6,"0.00")&" €)")))))) -> Esperar (menos de 10 clics) | W6: =B6&" | "&C6 -> soporte móvil para coche de pinza | Exacta
A7: =IFERROR(INDEX(Seguimiento!$D:$D,MATCH(W7&"#"&_xlfn.MAXIFS(Seguimiento!$A:$A,Seguimiento!$Q:$Q,W7),Seguimiento!$R:$R,0)),"Activado") -> Activado | B7: soporte móvil para coche de pinza | C7: Amplia | D7: =IFERROR(IF(_xlfn.MAXIFS(Seguimiento!$A:$A,Seguimiento!$Q:$Q,W7)=0,O7,SUMIFS(Seguimiento!$F:$F,Seguimiento!$Q:$Q,W7,Seguimiento!$A:$A,_xlfn.MAXIFS(Seguimiento!$A:$A,Seguimiento!$Q:$Q,W7))),O7) -> 0.41 | E7: =IFERROR(SUMIFS(Seguimiento!$G:$G,Seguimiento!$Q:$Q,W7,Seguimiento!$A:$A,_xlfn.MAXIFS(Seguimiento!$A:$A,Seguimiento!$Q:$Q,W7)),0) -> 0 | F7: =IFERROR(SUMIFS(Seguimiento!$H:$H,Seguimiento!$Q:$Q,W7,Seguimiento!$A:$A,_xlfn.MAXIFS(Seguimiento!$A:$A,Seguimiento!$Q:$Q,W7)),0) -> 0 | G7: =IFERROR(F7/E7,0) -> 0 | H7: =IFERROR(SUMIFS(Seguimiento!$I:$I,Seguimiento!$Q:$Q,W7,Seguimiento!$A:$A,_xlfn.MAXIFS(Seguimiento!$A:$A,Seguimiento!$Q:$Q,W7)),0) -> 0 | I7: =IFERROR(H7/F7,0) -> 0 | J7: =IFERROR(SUMIFS(Seguimiento!$J:$J,Seguimiento!$Q:$Q,W7,Seguimiento!$A:$A,_xlfn.MAXIFS(Seguimiento!$A:$A,Seguimiento!$Q:$Q,W7)),0) -> 0 | K7: =IFERROR(SUMIFS(Seguimiento!$K:$K,Seguimiento!$Q:$Q,W7,Seguimiento!$A:$A,_xlfn.MAXIFS(Seguimiento!$A:$A,Seguimiento!$Q:$Q,W7)),0) -> 0 | L7: =IFERROR(H7/K7,0) -> 0 | M7: =IFERROR(K7/H7,0) -> 0 | N7: Histórica | O7: 0.41 | P7: =ROUND(O7*(1-Leyenda!$B$11),2) -> 0.21 | Q7: =ROUND(O7*(1+Leyenda!$B$11),2) -> 0.62 | R7: 0.41 | S7: T-005 | T7: =IFERROR(IF(_xlfn.MAXIFS(Seguimiento!$A:$A,Seguimiento!$Q:$Q,W7)=0,"",_xlfn.MAXIFS(Seguimiento!$A:$A,Seguimiento!$Q:$Q,W7)),"") -> 46290 | U7: =IF(AND(F7>=Leyenda!$B$12,J7=0),"PAUSAR (≥15 clics sin venta)",IF(AND(D7<=P7,F7>=20,L7>0.5),"PAUSAR (puja mínima y ACOS>50%)","")) | V7: =IF(LEFT(U7,6)="PAUSAR","Pausar y crear ticket",IF(F7<Leyenda!$B$13,"Esperar (menos de 10 clics)",IF(J7=0,"Sin ventas aún: vigilar",IF(L7<0.3,"Subir 10-25% (máx. "&TEXT(MIN(Q7,R7),"0.00")&" €)",IF(L7<=Leyenda!$B$5,"En objetivo: no tocar",IF(L7<=0.5,"Bajar 10-25% (mín. "&TEXT(P7,"0.00")&" €)","Bajar 25-50% (mín. "&TEXT(P7,"0.00")&" €)")))))) -> Esperar (menos de 10 clics) | W7: =B7&" | "&C7 -> soporte móvil para coche de pinza | Amplia
A8: =IFERROR(INDEX(Seguimiento!$D:$D,MATCH(W8&"#"&_xlfn.MAXIFS(Seguimiento!$A:$A,Seguimiento!$Q:$Q,W8),Seguimiento!$R:$R,0)),"Activado") -> Activado | B8: soporte móvil para coche con pinza | C8: Amplia | D8: =IFERROR(IF(_xlfn.MAXIFS(Seguimiento!$A:$A,Seguimiento!$Q:$Q,W8)=0,O8,SUMIFS(Seguimiento!$F:$F,Seguimiento!$Q:$Q,W8,Seguimiento!$A:$A,_xlfn.MAXIFS(Seguimiento!$A:$A,Seguimiento!$Q:$Q,W8))),O8) -> 0.41 | E8: =IFERROR(SUMIFS(Seguimiento!$G:$G,Seguimiento!$Q:$Q,W8,Seguimiento!$A:$A,_xlfn.MAXIFS(Seguimiento!$A:$A,Seguimiento!$Q:$Q,W8)),0) -> 0 | F8: =IFERROR(SUMIFS(Seguimiento!$H:$H,Seguimiento!$Q:$Q,W8,Seguimiento!$A:$A,_xlfn.MAXIFS(Seguimiento!$A:$A,Seguimiento!$Q:$Q,W8)),0) -> 0 | G8: =IFERROR(F8/E8,0) -> 0 | H8: =IFERROR(SUMIFS(Seguimiento!$I:$I,Seguimiento!$Q:$Q,W8,Seguimiento!$A:$A,_xlfn.MAXIFS(Seguimiento!$A:$A,Seguimiento!$Q:$Q,W8)),0) -> 0 | I8: =IFERROR(H8/F8,0) -> 0 | J8: =IFERROR(SUMIFS(Seguimiento!$J:$J,Seguimiento!$Q:$Q,W8,Seguimiento!$A:$A,_xlfn.MAXIFS(Seguimiento!$A:$A,Seguimiento!$Q:$Q,W8)),0) -> 0 | K8: =IFERROR(SUMIFS(Seguimiento!$K:$K,Seguimiento!$Q:$Q,W8,Seguimiento!$A:$A,_xlfn.MAXIFS(Seguimiento!$A:$A,Seguimiento!$Q:$Q,W8)),0) -> 0 | L8: =IFERROR(H8/K8,0) -> 0 | M8: =IFERROR(K8/H8,0) -> 0 | N8: Histórica | O8: 0.41 | P8: =ROUND(O8*(1-Leyenda!$B$11),2) -> 0.21 | Q8: =ROUND(O8*(1+Leyenda!$B$11),2) -> 0.62 | R8: 0.44 | S8: T-006 | T8: =IFERROR(IF(_xlfn.MAXIFS(Seguimiento!$A:$A,Seguimiento!$Q:$Q,W8)=0,"",_xlfn.MAXIFS(Seguimiento!$A:$A,Seguimiento!$Q:$Q,W8)),"") -> 46290 | U8: =IF(AND(F8>=Leyenda!$B$12,J8=0),"PAUSAR (≥15 clics sin venta)",IF(AND(D8<=P8,F8>=20,L8>0.5),"PAUSAR (puja mínima y ACOS>50%)","")) | V8: =IF(LEFT(U8,6)="PAUSAR","Pausar y crear ticket",IF(F8<Leyenda!$B$13,"Esperar (menos de 10 clics)",IF(J8=0,"Sin ventas aún: vigilar",IF(L8<0.3,"Subir 10-25% (máx. "&TEXT(MIN(Q8,R8),"0.00")&" €)",IF(L8<=Leyenda!$B$5,"En objetivo: no tocar",IF(L8<=0.5,"Bajar 10-25% (mín. "&TEXT(P8,"0.00")&" €)","Bajar 25-50% (mín. "&TEXT(P8,"0.00")&" €)")))))) -> Esperar (menos de 10 clics) | W8: =B8&" | "&C8 -> soporte móvil para coche con pinza | Amplia
A9: =IFERROR(INDEX(Seguimiento!$D:$D,MATCH(W9&"#"&_xlfn.MAXIFS(Seguimiento!$A:$A,Seguimiento!$Q:$Q,W9),Seguimiento!$R:$R,0)),"Activado") -> Activado | B9: soporte móvil coche pinza 360 | C9: Frase | D9: =IFERROR(IF(_xlfn.MAXIFS(Seguimiento!$A:$A,Seguimiento!$Q:$Q,W9)=0,O9,SUMIFS(Seguimiento!$F:$F,Seguimiento!$Q:$Q,W9,Seguimiento!$A:$A,_xlfn.MAXIFS(Seguimiento!$A:$A,Seguimiento!$Q:$Q,W9))),O9) -> 0.44 | E9: =IFERROR(SUMIFS(Seguimiento!$G:$G,Seguimiento!$Q:$Q,W9,Seguimiento!$A:$A,_xlfn.MAXIFS(Seguimiento!$A:$A,Seguimiento!$Q:$Q,W9)),0) -> 0 | F9: =IFERROR(SUMIFS(Seguimiento!$H:$H,Seguimiento!$Q:$Q,W9,Seguimiento!$A:$A,_xlfn.MAXIFS(Seguimiento!$A:$A,Seguimiento!$Q:$Q,W9)),0) -> 0 | G9: =IFERROR(F9/E9,0) -> 0 | H9: =IFERROR(SUMIFS(Seguimiento!$I:$I,Seguimiento!$Q:$Q,W9,Seguimiento!$A:$A,_xlfn.MAXIFS(Seguimiento!$A:$A,Seguimiento!$Q:$Q,W9)),0) -> 0 | I9: =IFERROR(H9/F9,0) -> 0 | J9: =IFERROR(SUMIFS(Seguimiento!$J:$J,Seguimiento!$Q:$Q,W9,Seguimiento!$A:$A,_xlfn.MAXIFS(Seguimiento!$A:$A,Seguimiento!$Q:$Q,W9)),0) -> 0 | K9: =IFERROR(SUMIFS(Seguimiento!$K:$K,Seguimiento!$Q:$Q,W9,Seguimiento!$A:$A,_xlfn.MAXIFS(Seguimiento!$A:$A,Seguimiento!$Q:$Q,W9)),0) -> 0 | L9: =IFERROR(H9/K9,0) -> 0 | M9: =IFERROR(K9/H9,0) -> 0 | N9: Especial IA | O9: 0.44 | P9: =ROUND(O9*(1-Leyenda!$B$11),2) -> 0.22 | Q9: =ROUND(O9*(1+Leyenda!$B$11),2) -> 0.66 | R9: 0.44 | S9: T-007 | T9: =IFERROR(IF(_xlfn.MAXIFS(Seguimiento!$A:$A,Seguimiento!$Q:$Q,W9)=0,"",_xlfn.MAXIFS(Seguimiento!$A:$A,Seguimiento!$Q:$Q,W9)),"") -> 46290 | U9: =IF(AND(F9>=Leyenda!$B$12,J9=0),"PAUSAR (≥15 clics sin venta)",IF(AND(D9<=P9,F9>=20,L9>0.5),"PAUSAR (puja mínima y ACOS>50%)","")) | V9: =IF(LEFT(U9,6)="PAUSAR","Pausar y crear ticket",IF(F9<Leyenda!$B$13,"Esperar (menos de 10 clics)",IF(J9=0,"Sin ventas aún: vigilar",IF(L9<0.3,"Subir 10-25% (máx. "&TEXT(MIN(Q9,R9),"0.00")&" €)",IF(L9<=Leyenda!$B$5,"En objetivo: no tocar",IF(L9<=0.5,"Bajar 10-25% (mín. "&TEXT(P9,"0.00")&" €)","Bajar 25-50% (mín. "&TEXT(P9,"0.00")&" €)")))))) -> Esperar (menos de 10 clics) | W9: =B9&" | "&C9 -> soporte móvil coche pinza 360 | Frase
A10: =IFERROR(INDEX(Seguimiento!$D:$D,MATCH(W10&"#"&_xlfn.MAXIFS(Seguimiento!$A:$A,Seguimiento!$Q:$Q,W10),Seguimiento!$R:$R,0)),"Activado") -> Activado | B10: soporte móvil coche pinza para espejo retrovisor | C10: Frase | D10: =IFERROR(IF(_xlfn.MAXIFS(Seguimiento!$A:$A,Seguimiento!$Q:$Q,W10)=0,O10,SUMIFS(Seguimiento!$F:$F,Seguimiento!$Q:$Q,W10,Seguimiento!$A:$A,_xlfn.MAXIFS(Seguimiento!$A:$A,Seguimiento!$Q:$Q,W10))),O10) -> 0.46 | E10: =IFERROR(SUMIFS(Seguimiento!$G:$G,Seguimiento!$Q:$Q,W10,Seguimiento!$A:$A,_xlfn.MAXIFS(Seguimiento!$A:$A,Seguimiento!$Q:$Q,W10)),0) -> 0 | F10: =IFERROR(SUMIFS(Seguimiento!$H:$H,Seguimiento!$Q:$Q,W10,Seguimiento!$A:$A,_xlfn.MAXIFS(Seguimiento!$A:$A,Seguimiento!$Q:$Q,W10)),0) -> 0 | G10: =IFERROR(F10/E10,0) -> 0 | H10: =IFERROR(SUMIFS(Seguimiento!$I:$I,Seguimiento!$Q:$Q,W10,Seguimiento!$A:$A,_xlfn.MAXIFS(Seguimiento!$A:$A,Seguimiento!$Q:$Q,W10)),0) -> 0 | I10: =IFERROR(H10/F10,0) -> 0 | J10: =IFERROR(SUMIFS(Seguimiento!$J:$J,Seguimiento!$Q:$Q,W10,Seguimiento!$A:$A,_xlfn.MAXIFS(Seguimiento!$A:$A,Seguimiento!$Q:$Q,W10)),0) -> 0 | K10: =IFERROR(SUMIFS(Seguimiento!$K:$K,Seguimiento!$Q:$Q,W10,Seguimiento!$A:$A,_xlfn.MAXIFS(Seguimiento!$A:$A,Seguimiento!$Q:$Q,W10)),0) -> 0 | L10: =IFERROR(H10/K10,0) -> 0 | M10: =IFERROR(K10/H10,0) -> 0 | N10: Especial IA | O10: 0.46 | P10: =ROUND(O10*(1-Leyenda!$B$11),2) -> 0.23 | Q10: =ROUND(O10*(1+Leyenda!$B$11),2) -> 0.69 | R10: 0.46 | S10: T-008 | T10: =IFERROR(IF(_xlfn.MAXIFS(Seguimiento!$A:$A,Seguimiento!$Q:$Q,W10)=0,"",_xlfn.MAXIFS(Seguimiento!$A:$A,Seguimiento!$Q:$Q,W10)),"") -> 46290 | U10: =IF(AND(F10>=Leyenda!$B$12,J10=0),"PAUSAR (≥15 clics sin venta)",IF(AND(D10<=P10,F10>=20,L10>0.5),"PAUSAR (puja mínima y ACOS>50%)","")) | V10: =IF(LEFT(U10,6)="PAUSAR","Pausar y crear ticket",IF(F10<Leyenda!$B$13,"Esperar (menos de 10 clics)",IF(J10=0,"Sin ventas aún: vigilar",IF(L10<0.3,"Subir 10-25% (máx. "&TEXT(MIN(Q10,R10),"0.00")&" €)",IF(L10<=Leyenda!$B$5,"En objetivo: no tocar",IF(L10<=0.5,"Bajar 10-25% (mín. "&TEXT(P10,"0.00")&" €)","Bajar 25-50% (mín. "&TEXT(P10,"0.00")&" €)")))))) -> Esperar (menos de 10 clics) | W10: =B10&" | "&C10 -> soporte móvil coche pinza para espejo retrovisor | Frase
A11: =IFERROR(INDEX(Seguimiento!$D:$D,MATCH(W11&"#"&_xlfn.MAXIFS(Seguimiento!$A:$A,Seguimiento!$Q:$Q,W11),Seguimiento!$R:$R,0)),"Activado") -> Activado | B11: soporte móvil coche pinza para parasol | C11: Frase | D11: =IFERROR(IF(_xlfn.MAXIFS(Seguimiento!$A:$A,Seguimiento!$Q:$Q,W11)=0,O11,SUMIFS(Seguimiento!$F:$F,Seguimiento!$Q:$Q,W11,Seguimiento!$A:$A,_xlfn.MAXIFS(Seguimiento!$A:$A,Seguimiento!$Q:$Q,W11))),O11) -> 0.45 | E11: =IFERROR(SUMIFS(Seguimiento!$G:$G,Seguimiento!$Q:$Q,W11,Seguimiento!$A:$A,_xlfn.MAXIFS(Seguimiento!$A:$A,Seguimiento!$Q:$Q,W11)),0) -> 0 | F11: =IFERROR(SUMIFS(Seguimiento!$H:$H,Seguimiento!$Q:$Q,W11,Seguimiento!$A:$A,_xlfn.MAXIFS(Seguimiento!$A:$A,Seguimiento!$Q:$Q,W11)),0) -> 0 | G11: =IFERROR(F11/E11,0) -> 0 | H11: =IFERROR(SUMIFS(Seguimiento!$I:$I,Seguimiento!$Q:$Q,W11,Seguimiento!$A:$A,_xlfn.MAXIFS(Seguimiento!$A:$A,Seguimiento!$Q:$Q,W11)),0) -> 0 | I11: =IFERROR(H11/F11,0) -> 0 | J11: =IFERROR(SUMIFS(Seguimiento!$J:$J,Seguimiento!$Q:$Q,W11,Seguimiento!$A:$A,_xlfn.MAXIFS(Seguimiento!$A:$A,Seguimiento!$Q:$Q,W11)),0) -> 0 | K11: =IFERROR(SUMIFS(Seguimiento!$K:$K,Seguimiento!$Q:$Q,W11,Seguimiento!$A:$A,_xlfn.MAXIFS(Seguimiento!$A:$A,Seguimiento!$Q:$Q,W11)),0) -> 0 | L11: =IFERROR(H11/K11,0) -> 0 | M11: =IFERROR(K11/H11,0) -> 0 | N11: Especial IA | O11: 0.45 | P11: =ROUND(O11*(1-Leyenda!$B$11),2) -> 0.23 | Q11: =ROUND(O11*(1+Leyenda!$B$11),2) -> 0.68 | R11: 0.45 | S11: T-009 | T11: =IFERROR(IF(_xlfn.MAXIFS(Seguimiento!$A:$A,Seguimiento!$Q:$Q,W11)=0,"",_xlfn.MAXIFS(Seguimiento!$A:$A,Seguimiento!$Q:$Q,W11)),"") -> 46290 | U11: =IF(AND(F11>=Leyenda!$B$12,J11=0),"PAUSAR (≥15 clics sin venta)",IF(AND(D11<=P11,F11>=20,L11>0.5),"PAUSAR (puja mínima y ACOS>50%)","")) | V11: =IF(LEFT(U11,6)="PAUSAR","Pausar y crear ticket",IF(F11<Leyenda!$B$13,"Esperar (menos de 10 clics)",IF(J11=0,"Sin ventas aún: vigilar",IF(L11<0.3,"Subir 10-25% (máx. "&TEXT(MIN(Q11,R11),"0.00")&" €)",IF(L11<=Leyenda!$B$5,"En objetivo: no tocar",IF(L11<=0.5,"Bajar 10-25% (mín. "&TEXT(P11,"0.00")&" €)","Bajar 25-50% (mín. "&TEXT(P11,"0.00")&" €)")))))) -> Esperar (menos de 10 clics) | W11: =B11&" | "&C11 -> soporte móvil coche pinza para parasol | Frase
A12: =IFERROR(INDEX(Seguimiento!$D:$D,MATCH(W12&"#"&_xlfn.MAXIFS(Seguimiento!$A:$A,Seguimiento!$Q:$Q,W12),Seguimiento!$R:$R,0)),"Activado") -> Activado | B12: soporte móvil coche pinza ajustable | C12: Frase | D12: =IFERROR(IF(_xlfn.MAXIFS(Seguimiento!$A:$A,Seguimiento!$Q:$Q,W12)=0,O12,SUMIFS(Seguimiento!$F:$F,Seguimiento!$Q:$Q,W12,Seguimiento!$A:$A,_xlfn.MAXIFS(Seguimiento!$A:$A,Seguimiento!$Q:$Q,W12))),O12) -> 0.45 | E12: =IFERROR(SUMIFS(Seguimiento!$G:$G,Seguimiento!$Q:$Q,W12,Seguimiento!$A:$A,_xlfn.MAXIFS(Seguimiento!$A:$A,Seguimiento!$Q:$Q,W12)),0) -> 0 | F12: =IFERROR(SUMIFS(Seguimiento!$H:$H,Seguimiento!$Q:$Q,W12,Seguimiento!$A:$A,_xlfn.MAXIFS(Seguimiento!$A:$A,Seguimiento!$Q:$Q,W12)),0) -> 0 | G12: =IFERROR(F12/E12,0) -> 0 | H12: =IFERROR(SUMIFS(Seguimiento!$I:$I,Seguimiento!$Q:$Q,W12,Seguimiento!$A:$A,_xlfn.MAXIFS(Seguimiento!$A:$A,Seguimiento!$Q:$Q,W12)),0) -> 0 | I12: =IFERROR(H12/F12,0) -> 0 | J12: =IFERROR(SUMIFS(Seguimiento!$J:$J,Seguimiento!$Q:$Q,W12,Seguimiento!$A:$A,_xlfn.MAXIFS(Seguimiento!$A:$A,Seguimiento!$Q:$Q,W12)),0) -> 0 | K12: =IFERROR(SUMIFS(Seguimiento!$K:$K,Seguimiento!$Q:$Q,W12,Seguimiento!$A:$A,_xlfn.MAXIFS(Seguimiento!$A:$A,Seguimiento!$Q:$Q,W12)),0) -> 0 | L12: =IFERROR(H12/K12,0) -> 0 | M12: =IFERROR(K12/H12,0) -> 0 | N12: Especial IA | O12: 0.45 | P12: =ROUND(O12*(1-Leyenda!$B$11),2) -> 0.23 | Q12: =ROUND(O12*(1+Leyenda!$B$11),2) -> 0.68 | R12: 0.45 | S12: T-010 | T12: =IFERROR(IF(_xlfn.MAXIFS(Seguimiento!$A:$A,Seguimiento!$Q:$Q,W12)=0,"",_xlfn.MAXIFS(Seguimiento!$A:$A,Seguimiento!$Q:$Q,W12)),"") -> 46290 | U12: =IF(AND(F12>=Leyenda!$B$12,J12=0),"PAUSAR (≥15 clics sin venta)",IF(AND(D12<=P12,F12>=20,L12>0.5),"PAUSAR (puja mínima y ACOS>50%)","")) | V12: =IF(LEFT(U12,6)="PAUSAR","Pausar y crear ticket",IF(F12<Leyenda!$B$13,"Esperar (menos de 10 clics)",IF(J12=0,"Sin ventas aún: vigilar",IF(L12<0.3,"Subir 10-25% (máx. "&TEXT(MIN(Q12,R12),"0.00")&" €)",IF(L12<=Leyenda!$B$5,"En objetivo: no tocar",IF(L12<=0.5,"Bajar 10-25% (mín. "&TEXT(P12,"0.00")&" €)","Bajar 25-50% (mín. "&TEXT(P12,"0.00")&" €)")))))) -> Esperar (menos de 10 clics) | W12: =B12&" | "&C12 -> soporte móvil coche pinza ajustable | Frase
A13: =IFERROR(INDEX(Seguimiento!$D:$D,MATCH(W13&"#"&_xlfn.MAXIFS(Seguimiento!$A:$A,Seguimiento!$Q:$Q,W13),Seguimiento!$R:$R,0)),"Activado") -> Activado | B13: soporte móvil coche pinza para iphone | C13: Frase | D13: =IFERROR(IF(_xlfn.MAXIFS(Seguimiento!$A:$A,Seguimiento!$Q:$Q,W13)=0,O13,SUMIFS(Seguimiento!$F:$F,Seguimiento!$Q:$Q,W13,Seguimiento!$A:$A,_xlfn.MAXIFS(Seguimiento!$A:$A,Seguimiento!$Q:$Q,W13))),O13) -> 0.45 | E13: =IFERROR(SUMIFS(Seguimiento!$G:$G,Seguimiento!$Q:$Q,W13,Seguimiento!$A:$A,_xlfn.MAXIFS(Seguimiento!$A:$A,Seguimiento!$Q:$Q,W13)),0) -> 0 | F13: =IFERROR(SUMIFS(Seguimiento!$H:$H,Seguimiento!$Q:$Q,W13,Seguimiento!$A:$A,_xlfn.MAXIFS(Seguimiento!$A:$A,Seguimiento!$Q:$Q,W13)),0) -> 0 | G13: =IFERROR(F13/E13,0) -> 0 | H13: =IFERROR(SUMIFS(Seguimiento!$I:$I,Seguimiento!$Q:$Q,W13,Seguimiento!$A:$A,_xlfn.MAXIFS(Seguimiento!$A:$A,Seguimiento!$Q:$Q,W13)),0) -> 0 | I13: =IFERROR(H13/F13,0) -> 0 | J13: =IFERROR(SUMIFS(Seguimiento!$J:$J,Seguimiento!$Q:$Q,W13,Seguimiento!$A:$A,_xlfn.MAXIFS(Seguimiento!$A:$A,Seguimiento!$Q:$Q,W13)),0) -> 0 | K13: =IFERROR(SUMIFS(Seguimiento!$K:$K,Seguimiento!$Q:$Q,W13,Seguimiento!$A:$A,_xlfn.MAXIFS(Seguimiento!$A:$A,Seguimiento!$Q:$Q,W13)),0) -> 0 | L13: =IFERROR(H13/K13,0) -> 0 | M13: =IFERROR(K13/H13,0) -> 0 | N13: Especial IA | O13: 0.45 | P13: =ROUND(O13*(1-Leyenda!$B$11),2) -> 0.23 | Q13: =ROUND(O13*(1+Leyenda!$B$11),2) -> 0.68 | R13: 0.45 | S13: T-011 | T13: =IFERROR(IF(_xlfn.MAXIFS(Seguimiento!$A:$A,Seguimiento!$Q:$Q,W13)=0,"",_xlfn.MAXIFS(Seguimiento!$A:$A,Seguimiento!$Q:$Q,W13)),"") -> 46290 | U13: =IF(AND(F13>=Leyenda!$B$12,J13=0),"PAUSAR (≥15 clics sin venta)",IF(AND(D13<=P13,F13>=20,L13>0.5),"PAUSAR (puja mínima y ACOS>50%)","")) | V13: =IF(LEFT(U13,6)="PAUSAR","Pausar y crear ticket",IF(F13<Leyenda!$B$13,"Esperar (menos de 10 clics)",IF(J13=0,"Sin ventas aún: vigilar",IF(L13<0.3,"Subir 10-25% (máx. "&TEXT(MIN(Q13,R13),"0.00")&" €)",IF(L13<=Leyenda!$B$5,"En objetivo: no tocar",IF(L13<=0.5,"Bajar 10-25% (mín. "&TEXT(P13,"0.00")&" €)","Bajar 25-50% (mín. "&TEXT(P13,"0.00")&" €)")))))) -> Esperar (menos de 10 clics) | W13: =B13&" | "&C13 -> soporte móvil coche pinza para iphone | Frase
A14: =IFERROR(INDEX(Seguimiento!$D:$D,MATCH(W14&"#"&_xlfn.MAXIFS(Seguimiento!$A:$A,Seguimiento!$Q:$Q,W14),Seguimiento!$R:$R,0)),"Activado") -> Activado | B14: asin="B07H996QMD" | C14: Producto | D14: =IFERROR(IF(_xlfn.MAXIFS(Seguimiento!$A:$A,Seguimiento!$Q:$Q,W14)=0,O14,SUMIFS(Seguimiento!$F:$F,Seguimiento!$Q:$Q,W14,Seguimiento!$A:$A,_xlfn.MAXIFS(Seguimiento!$A:$A,Seguimiento!$Q:$Q,W14))),O14) -> 0.3 | E14: =IFERROR(SUMIFS(Seguimiento!$G:$G,Seguimiento!$Q:$Q,W14,Seguimiento!$A:$A,_xlfn.MAXIFS(Seguimiento!$A:$A,Seguimiento!$Q:$Q,W14)),0) -> 0 | F14: =IFERROR(SUMIFS(Seguimiento!$H:$H,Seguimiento!$Q:$Q,W14,Seguimiento!$A:$A,_xlfn.MAXIFS(Seguimiento!$A:$A,Seguimiento!$Q:$Q,W14)),0) -> 0 | G14: =IFERROR(F14/E14,0) -> 0 | H14: =IFERROR(SUMIFS(Seguimiento!$I:$I,Seguimiento!$Q:$Q,W14,Seguimiento!$A:$A,_xlfn.MAXIFS(Seguimiento!$A:$A,Seguimiento!$Q:$Q,W14)),0) -> 0 | I14: =IFERROR(H14/F14,0) -> 0 | J14: =IFERROR(SUMIFS(Seguimiento!$J:$J,Seguimiento!$Q:$Q,W14,Seguimiento!$A:$A,_xlfn.MAXIFS(Seguimiento!$A:$A,Seguimiento!$Q:$Q,W14)),0) -> 0 | K14: =IFERROR(SUMIFS(Seguimiento!$K:$K,Seguimiento!$Q:$Q,W14,Seguimiento!$A:$A,_xlfn.MAXIFS(Seguimiento!$A:$A,Seguimiento!$Q:$Q,W14)),0) -> 0 | L14: =IFERROR(H14/K14,0) -> 0 | M14: =IFERROR(K14/H14,0) -> 0 | N14: Prueba producto | O14: 0.3 | P14: =ROUND(O14*(1-Leyenda!$B$11),2) -> 0.15 | Q14: =ROUND(O14*(1+Leyenda!$B$11),2) -> 0.45 | R14: 0.32 | S14: T-014 | T14: =IFERROR(IF(_xlfn.MAXIFS(Seguimiento!$A:$A,Seguimiento!$Q:$Q,W14)=0,"",_xlfn.MAXIFS(Seguimiento!$A:$A,Seguimiento!$Q:$Q,W14)),"") -> 46290 | U14: =IF(AND(F14>=Leyenda!$B$12,J14=0),"PAUSAR (≥15 clics sin venta)",IF(AND(D14<=P14,F14>=20,L14>0.5),"PAUSAR (puja mínima y ACOS>50%)","")) | V14: =IF(LEFT(U14,6)="PAUSAR","Pausar y crear ticket",IF(F14<Leyenda!$B$13,"Esperar (menos de 10 clics)",IF(J14=0,"Sin ventas aún: vigilar",IF(L14<0.3,"Subir 10-25% (máx. "&TEXT(MIN(Q14,R14),"0.00")&" €)",IF(L14<=Leyenda!$B$5,"En objetivo: no tocar",IF(L14<=0.5,"Bajar 10-25% (mín. "&TEXT(P14,"0.00")&" €)","Bajar 25-50% (mín. "&TEXT(P14,"0.00")&" €)")))))) -> Esperar (menos de 10 clics) | W14: =B14&" | "&C14 -> asin="B07H996QMD" | Producto
A15: =IFERROR(INDEX(Seguimiento!$D:$D,MATCH(W15&"#"&_xlfn.MAXIFS(Seguimiento!$A:$A,Seguimiento!$Q:$Q,W15),Seguimiento!$R:$R,0)),"Activado") -> Activado | B15: asin="B0BS1TQJH2" | C15: Producto | D15: =IFERROR(IF(_xlfn.MAXIFS(Seguimiento!$A:$A,Seguimiento!$Q:$Q,W15)=0,O15,SUMIFS(Seguimiento!$F:$F,Seguimiento!$Q:$Q,W15,Seguimiento!$A:$A,_xlfn.MAXIFS(Seguimiento!$A:$A,Seguimiento!$Q:$Q,W15))),O15) -> 0.3 | E15: =IFERROR(SUMIFS(Seguimiento!$G:$G,Seguimiento!$Q:$Q,W15,Seguimiento!$A:$A,_xlfn.MAXIFS(Seguimiento!$A:$A,Seguimiento!$Q:$Q,W15)),0) -> 0 | F15: =IFERROR(SUMIFS(Seguimiento!$H:$H,Seguimiento!$Q:$Q,W15,Seguimiento!$A:$A,_xlfn.MAXIFS(Seguimiento!$A:$A,Seguimiento!$Q:$Q,W15)),0) -> 0 | G15: =IFERROR(F15/E15,0) -> 0 | H15: =IFERROR(SUMIFS(Seguimiento!$I:$I,Seguimiento!$Q:$Q,W15,Seguimiento!$A:$A,_xlfn.MAXIFS(Seguimiento!$A:$A,Seguimiento!$Q:$Q,W15)),0) -> 0 | I15: =IFERROR(H15/F15,0) -> 0 | J15: =IFERROR(SUMIFS(Seguimiento!$J:$J,Seguimiento!$Q:$Q,W15,Seguimiento!$A:$A,_xlfn.MAXIFS(Seguimiento!$A:$A,Seguimiento!$Q:$Q,W15)),0) -> 0 | K15: =IFERROR(SUMIFS(Seguimiento!$K:$K,Seguimiento!$Q:$Q,W15,Seguimiento!$A:$A,_xlfn.MAXIFS(Seguimiento!$A:$A,Seguimiento!$Q:$Q,W15)),0) -> 0 | L15: =IFERROR(H15/K15,0) -> 0 | M15: =IFERROR(K15/H15,0) -> 0 | N15: Prueba producto | O15: 0.3 | P15: =ROUND(O15*(1-Leyenda!$B$11),2) -> 0.15 | Q15: =ROUND(O15*(1+Leyenda!$B$11),2) -> 0.45 | R15: 0.32 | S15: T-015 | T15: =IFERROR(IF(_xlfn.MAXIFS(Seguimiento!$A:$A,Seguimiento!$Q:$Q,W15)=0,"",_xlfn.MAXIFS(Seguimiento!$A:$A,Seguimiento!$Q:$Q,W15)),"") -> 46290 | U15: =IF(AND(F15>=Leyenda!$B$12,J15=0),"PAUSAR (≥15 clics sin venta)",IF(AND(D15<=P15,F15>=20,L15>0.5),"PAUSAR (puja mínima y ACOS>50%)","")) | V15: =IF(LEFT(U15,6)="PAUSAR","Pausar y crear ticket",IF(F15<Leyenda!$B$13,"Esperar (menos de 10 clics)",IF(J15=0,"Sin ventas aún: vigilar",IF(L15<0.3,"Subir 10-25% (máx. "&TEXT(MIN(Q15,R15),"0.00")&" €)",IF(L15<=Leyenda!$B$5,"En objetivo: no tocar",IF(L15<=0.5,"Bajar 10-25% (mín. "&TEXT(P15,"0.00")&" €)","Bajar 25-50% (mín. "&TEXT(P15,"0.00")&" €)")))))) -> Esperar (menos de 10 clics) | W15: =B15&" | "&C15 -> asin="B0BS1TQJH2" | Producto
... A18: =IFERROR(INDEX(Seguimiento!$D:$D,MATCH(W18&"#"&_xlfn.MAXIFS(Seguimiento!$A:$A,Seguimiento!$Q:$Q,W18),Seguimiento!$R:$R,0)),"Activado") -> Activado | B18: categoría="Soportes montados en salpicadero para automóviles" precio>12€ estrellas≤4 | C18: Categoría | D18: =IFERROR(IF(_xlfn.MAXIFS(Seguimiento!$A:$A,Seguimiento!$Q:$Q,W18)=0,O18,SUMIFS(Seguimiento!$F:$F,Seguimiento!$Q:$Q,W18,Seguimiento!$A:$A,_xlfn.MAXIFS(Seguimiento!$A:$A,Seguimiento!$Q:$Q,W18))),O18) -> 0.3 | E18: =IFERROR(SUMIFS(Seguimiento!$G:$G,Seguimiento!$Q:$Q,W18,Seguimiento!$A:$A,_xlfn.MAXIFS(Seguimiento!$A:$A,Seguimiento!$Q:$Q,W18)),0) -> 0 | F18: =IFERROR(SUMIFS(Seguimiento!$H:$H,Seguimiento!$Q:$Q,W18,Seguimiento!$A:$A,_xlfn.MAXIFS(Seguimiento!$A:$A,Seguimiento!$Q:$Q,W18)),0) -> 0 | G18: =IFERROR(F18/E18,0) -> 0 | H18: =IFERROR(SUMIFS(Seguimiento!$I:$I,Seguimiento!$Q:$Q,W18,Seguimiento!$A:$A,_xlfn.MAXIFS(Seguimiento!$A:$A,Seguimiento!$Q:$Q,W18)),0) -> 0 | I18: =IFERROR(H18/F18,0) -> 0 | J18: =IFERROR(SUMIFS(Seguimiento!$J:$J,Seguimiento!$Q:$Q,W18,Seguimiento!$A:$A,_xlfn.MAXIFS(Seguimiento!$A:$A,Seguimiento!$Q:$Q,W18)),0) -> 0 | K18: =IFERROR(SUMIFS(Seguimiento!$K:$K,Seguimiento!$Q:$Q,W18,Seguimiento!$A:$A,_xlfn.MAXIFS(Seguimiento!$A:$A,Seguimiento!$Q:$Q,W18)),0) -> 0 | L18: =IFERROR(H18/K18,0) -> 0 | M18: =IFERROR(K18/H18,0) -> 0 | N18: Prueba categoría | O18: 0.3 | P18: =ROUND(O18*(1-Leyenda!$B$11),2) -> 0.15 | Q18: =ROUND(O18*(1+Leyenda!$B$11),2) -> 0.45 | R18: 0.32 | S18: T-018 | T18: =IFERROR(IF(_xlfn.MAXIFS(Seguimiento!$A:$A,Seguimiento!$Q:$Q,W18)=0,"",_xlfn.MAXIFS(Seguimiento!$A:$A,Seguimiento!$Q:$Q,W18)),"") -> 46290 | U18: =IF(AND(F18>=Leyenda!$B$12,J18=0),"PAUSAR (≥15 clics sin venta)",IF(AND(D18<=P18,F18>=20,L18>0.5),"PAUSAR (puja mínima y ACOS>50%)","")) | V18: =IF(LEFT(U18,6)="PAUSAR","Pausar y crear ticket",IF(F18<Leyenda!$B$13,"Esperar (menos de 10 clics)",IF(J18=0,"Sin ventas aún: vigilar",IF(L18<0.3,"Subir 10-25% (máx. "&TEXT(MIN(Q18,R18),"0.00")&" €)",IF(L18<=Leyenda!$B$5,"En objetivo: no tocar",IF(L18<=0.5,"Bajar 10-25% (mín. "&TEXT(P18,"0.00")&" €)","Bajar 25-50% (mín. "&TEXT(P18,"0.00")&" €)")))))) -> Esperar (menos de 10 clics) | W18: =B18&" | "&C18 -> categoría="Soportes montados en salpicadero para automóviles" precio>12€ estrellas≤4 | Categoría
B19: TOTAL GRUPO | E19: =SUM(E4:E18) -> 0 | F19: =SUM(F4:F18) -> 0 | G19: =IFERROR(F19/E19,0) -> 0 | H19: =SUM(H4:H18) -> 0 | I19: =IFERROR(H19/F19,0) -> 0 | J19: =SUM(J4:J18) -> 0 | K19: =SUM(K4:K18) -> 0 | L19: =IFERROR(H19/K19,0) -> 0 | M19: =IFERROR(K19/H19,0) -> 0

Sheet Seguimiento
A1: Seguimiento — una fila por keyword en cada revisión (cada 3 días). Datos ACUMULADOS desde la creación del grupo, copiados del export de Segmentación de Amazon Ads.
A3: Fecha | B3: Palabra clave | C3: Tipo de coincidencia objetivo | D3: Estado | E3: Ticket | F3: Puja (EUR) | G3: Impresiones | H3: Clics | I3: Coste total (EUR) | J3: Compras | K3: Ventas (EUR) | L3: CTR | M3: CPC (EUR) | N3: ACOS | O3: ROAS | P3: Nota | Q3: Clave | R3: Clave+fecha
A4: 46290 | B4: soporte móvil para coche con pinza | C4: Frase | D4: Activado | E4: T-002 | F4: 0.78 | G4: 0 | H4: 0 | I4: 0 | J4: 0 | K4: 0 | L4: =IF(B4="","",IFERROR(H4/G4,0)) -> 0 | M4: =IF(B4="","",IFERROR(I4/H4,0)) -> 0 | N4: =IF(B4="","",IFERROR(I4/K4,0)) -> 0 | O4: =IF(B4="","",IFERROR(K4/I4,0)) -> 0 | P4: Día 0: creación del grupo (sin datos todavía) | Q4: =IF(B4="","",B4&" | "&C4) -> soporte móvil para coche con pinza | Frase | R4: =IF(B4="","",Q4&"#"&A4) -> soporte móvil para coche con pinza | Frase#46290
A5: 46290 | B5: soporte móvil para coche de pinza para salpicadero | C5: Amplia | D5: Activado | E5: T-003 | F5: 0.3 | G5: 0 | H5: 0 | I5: 0 | J5: 0 | K5: 0 | L5: =IF(B5="","",IFERROR(H5/G5,0)) -> 0 | M5: =IF(B5="","",IFERROR(I5/H5,0)) -> 0 | N5: =IF(B5="","",IFERROR(I5/K5,0)) -> 0 | O5: =IF(B5="","",IFERROR(K5/I5,0)) -> 0 | P5: Día 0: creación del grupo (sin datos todavía) | Q5: =IF(B5="","",B5&" | "&C5) -> soporte móvil para coche de pinza para salpicadero | Amplia | R5: =IF(B5="","",Q5&"#"&A5) -> soporte móvil para coche de pinza para salpicadero | Amplia#46290
A6: 46290 | B6: soporte móvil para coche de pinza | C6: Exacta | D6: Activado | E6: T-004 | F6: 0.51 | G6: 0 | H6: 0 | I6: 0 | J6: 0 | K6: 0 | L6: =IF(B6="","",IFERROR(H6/G6,0)) -> 0 | M6: =IF(B6="","",IFERROR(I6/H6,0)) -> 0 | N6: =IF(B6="","",IFERROR(I6/K6,0)) -> 0 | O6: =IF(B6="","",IFERROR(K6/I6,0)) -> 0 | P6: Día 0: creación del grupo (sin datos todavía) | Q6: =IF(B6="","",B6&" | "&C6) -> soporte móvil para coche de pinza | Exacta | R6: =IF(B6="","",Q6&"#"&A6) -> soporte móvil para coche de pinza | Exacta#46290
A7: 46290 | B7: soporte móvil para coche de pinza | C7: Amplia | D7: Activado | E7: T-005 | F7: 0.41 | G7: 0 | H7: 0 | I7: 0 | J7: 0 | K7: 0 | L7: =IF(B7="","",IFERROR(H7/G7,0)) -> 0 | M7: =IF(B7="","",IFERROR(I7/H7,0)) -> 0 | N7: =IF(B7="","",IFERROR(I7/K7,0)) -> 0 | O7: =IF(B7="","",IFERROR(K7/I7,0)) -> 0 | P7: Día 0: creación del grupo (sin datos todavía) | Q7: =IF(B7="","",B7&" | "&C7) -> soporte móvil para coche de pinza | Amplia | R7: =IF(B7="","",Q7&"#"&A7) -> soporte móvil para coche de pinza | Amplia#46290
A8: 46290 | B8: soporte móvil para coche con pinza | C8: Amplia | D8: Activado | E8: T-006 | F8: 0.41 | G8: 0 | H8: 0 | I8: 0 | J8: 0 | K8: 0 | L8: =IF(B8="","",IFERROR(H8/G8,0)) -> 0 | M8: =IF(B8="","",IFERROR(I8/H8,0)) -> 0 | N8: =IF(B8="","",IFERROR(I8/K8,0)) -> 0 | O8: =IF(B8="","",IFERROR(K8/I8,0)) -> 0 | P8: Día 0: creación del grupo (sin datos todavía) | Q8: =IF(B8="","",B8&" | "&C8) -> soporte móvil para coche con pinza | Amplia | R8: =IF(B8="","",Q8&"#"&A8) -> soporte móvil para coche con pinza | Amplia#46290
A9: 46290 | B9: soporte móvil coche pinza 360 | C9: Frase | D9: Activado | E9: T-007 | F9: 0.44 | G9: 0 | H9: 0 | I9: 0 | J9: 0 | K9: 0 | L9: =IF(B9="","",IFERROR(H9/G9,0)) -> 0 | M9: =IF(B9="","",IFERROR(I9/H9,0)) -> 0 | N9: =IF(B9="","",IFERROR(I9/K9,0)) -> 0 | O9: =IF(B9="","",IFERROR(K9/I9,0)) -> 0 | P9: Día 0: creación del grupo (sin datos todavía) | Q9: =IF(B9="","",B9&" | "&C9) -> soporte móvil coche pinza 360 | Frase | R9: =IF(B9="","",Q9&"#"&A9) -> soporte móvil coche pinza 360 | Frase#46290
A10: 46290 | B10: soporte móvil coche pinza para espejo retrovisor | C10: Frase | D10: Activado | E10: T-008 | F10: 0.46 | G10: 0 | H10: 0 | I10: 0 | J10: 0 | K10: 0 | L10: =IF(B10="","",IFERROR(H10/G10,0)) -> 0 | M10: =IF(B10="","",IFERROR(I10/H10,0)) -> 0 | N10: =IF(B10="","",IFERROR(I10/K10,0)) -> 0 | O10: =IF(B10="","",IFERROR(K10/I10,0)) -> 0 | P10: Día 0: creación del grupo (sin datos todavía) | Q10: =IF(B10="","",B10&" | "&C10) -> soporte móvil coche pinza para espejo retrovisor | Frase | R10: =IF(B10="","",Q10&"#"&A10) -> soporte móvil coche pinza para espejo retrovisor | Frase#46290
A11: 46290 | B11: soporte móvil coche pinza para parasol | C11: Frase | D11: Activado | E11: T-009 | F11: 0.45 | G11: 0 | H11: 0 | I11: 0 | J11: 0 | K11: 0 | L11: =IF(B11="","",IFERROR(H11/G11,0)) -> 0 | M11: =IF(B11="","",IFERROR(I11/H11,0)) -> 0 | N11: =IF(B11="","",IFERROR(I11/K11,0)) -> 0 | O11: =IF(B11="","",IFERROR(K11/I11,0)) -> 0 | P11: Día 0: creación del grupo (sin datos todavía) | Q11: =IF(B11="","",B11&" | "&C11) -> soporte móvil coche pinza para parasol | Frase | R11: =IF(B11="","",Q11&"#"&A11) -> soporte móvil coche pinza para parasol | Frase#46290
A12: 46290 | B12: soporte móvil coche pinza ajustable | C12: Frase | D12: Activado | E12: T-010 | F12: 0.45 | G12: 0 | H12: 0 | I12: 0 | J12: 0 | K12: 0 | L12: =IF(B12="","",IFERROR(H12/G12,0)) -> 0 | M12: =IF(B12="","",IFERROR(I12/H12,0)) -> 0 | N12: =IF(B12="","",IFERROR(I12/K12,0)) -> 0 | O12: =IF(B12="","",IFERROR(K12/I12,0)) -> 0 | P12: Día 0: creación del grupo (sin datos todavía) | Q12: =IF(B12="","",B12&" | "&C12) -> soporte móvil coche pinza ajustable | Frase | R12: =IF(B12="","",Q12&"#"&A12) -> soporte móvil coche pinza ajustable | Frase#46290
A13: 46290 | B13: soporte móvil coche pinza para iphone | C13: Frase | D13: Activado | E13: T-011 | F13: 0.45 | G13: 0 | H13: 0 | I13: 0 | J13: 0 | K13: 0 | L13: =IF(B13="","",IFERROR(H13/G13,0)) -> 0 | M13: =IF(B13="","",IFERROR(I13/H13,0)) -> 0 | N13: =IF(B13="","",IFERROR(I13/K13,0)) -> 0 | O13: =IF(B13="","",IFERROR(K13/I13,0)) -> 0 | P13: Día 0: creación del grupo (sin datos todavía) | Q13: =IF(B13="","",B13&" | "&C13) -> soporte móvil coche pinza para iphone | Frase | R13: =IF(B13="","",Q13&"#"&A13) -> soporte móvil coche pinza para iphone | Frase#46290
A14: 46290 | B14: asin="B07H996QMD" | C14: Producto | D14: Activado | E14: T-014 | F14: 0.3 | G14: 0 | H14: 0 | I14: 0 | J14: 0 | K14: 0 | L14: =IF(B14="","",IFERROR(H14/G14,0)) -> 0 | M14: =IF(B14="","",IFERROR(I14/H14,0)) -> 0 | N14: =IF(B14="","",IFERROR(I14/K14,0)) -> 0 | O14: =IF(B14="","",IFERROR(K14/I14,0)) -> 0 | P14: Día 0: creación del grupo (sin datos todavía) | Q14: =IF(B14="","",B14&" | "&C14) -> asin="B07H996QMD" | Producto | R14: =IF(B14="","",Q14&"#"&A14) -> asin="B07H996QMD" | Producto#46290
A15: 46290 | B15: asin="B0BS1TQJH2" | C15: Producto | D15: Activado | E15: T-015 | F15: 0.3 | G15: 0 | H15: 0 | I15: 0 | J15: 0 | K15: 0 | L15: =IF(B15="","",IFERROR(H15/G15,0)) -> 0 | M15: =IF(B15="","",IFERROR(I15/H15,0)) -> 0 | N15: =IF(B15="","",IFERROR(I15/K15,0)) -> 0 | O15: =IF(B15="","",IFERROR(K15/I15,0)) -> 0 | P15: Día 0: creación del grupo (sin datos todavía) | Q15: =IF(B15="","",B15&" | "&C15) -> asin="B0BS1TQJH2" | Producto | R15: =IF(B15="","",Q15&"#"&A15) -> asin="B0BS1TQJH2" | Producto#46290
... A18: 46290 | B18: categoría="Soportes montados en salpicadero para automóviles" precio>12€ estrellas≤4 | C18: Categoría | D18: Activado | E18: T-018 | F18: 0.3 | G18: 0 | H18: 0 | I18: 0 | J18: 0 | K18: 0 | L18: =IF(B18="","",IFERROR(H18/G18,0)) -> 0 | M18: =IF(B18="","",IFERROR(I18/H18,0)) -> 0 | N18: =IF(B18="","",IFERROR(I18/K18,0)) -> 0 | O18: =IF(B18="","",IFERROR(K18/I18,0)) -> 0 | P18: Día 0: creación del grupo (sin datos todavía) | Q18: =IF(B18="","",B18&" | "&C18) -> categoría="Soportes montados en salpicadero para automóviles" precio>12€ estrellas≤4 | Categoría | R18: =IF(B18="","",Q18&"#"&A18) -> categoría="Soportes montados en salpicadero para automóviles" precio>12€ estrellas≤4 | Categoría#46290
L19: =IF(B19="","",IFERROR(H19/G19,0)) | M19: =IF(B19="","",IFERROR(I19/H19,0)) | N19: =IF(B19="","",IFERROR(I19/K19,0)) | O19: =IF(B19="","",IFERROR(K19/I19,0)) | Q19: =IF(B19="","",B19&" | "&C19) | R19: =IF(B19="","",Q19&"#"&A19)
L20: =IF(B20="","",IFERROR(H20/G20,0)) | M20: =IF(B20="","",IFERROR(I20/H20,0)) | N20: =IF(B20="","",IFERROR(I20/K20,0)) | O20: =IF(B20="","",IFERROR(K20/I20,0)) | Q20: =IF(B20="","",B20&" | "&C20) | R20: =IF(B20="","",Q20&"#"&A20)
L21: =IF(B21="","",IFERROR(H21/G21,0)) | M21: =IF(B21="","",IFERROR(I21/H21,0)) | N21: =IF(B21="","",IFERROR(I21/K21,0)) | O21: =IF(B21="","",IFERROR(K21/I21,0)) | Q21: =IF(B21="","",B21&" | "&C21) | R21: =IF(B21="","",Q21&"#"&A21)
L22: =IF(B22="","",IFERROR(H22/G22,0)) | M22: =IF(B22="","",IFERROR(I22/H22,0)) | N22: =IF(B22="","",IFERROR(I22/K22,0)) | O22: =IF(B22="","",IFERROR(K22/I22,0)) | Q22: =IF(B22="","",B22&" | "&C22) | R22: =IF(B22="","",Q22&"#"&A22)
L23: =IF(B23="","",IFERROR(H23/G23,0)) | M23: =IF(B23="","",IFERROR(I23/H23,0)) | N23: =IF(B23="","",IFERROR(I23/K23,0)) | O23: =IF(B23="","",IFERROR(K23/I23,0)) | Q23: =IF(B23="","",B23&" | "&C23) | R23: =IF(B23="","",Q23&"#"&A23)
L24: =IF(B24="","",IFERROR(H24/G24,0)) | M24: =IF(B24="","",IFERROR(I24/H24,0)) | N24: =IF(B24="","",IFERROR(I24/K24,0)) | O24: =IF(B24="","",IFERROR(K24/I24,0)) | Q24: =IF(B24="","",B24&" | "&C24) | R24: =IF(B24="","",Q24&"#"&A24)
L25: =IF(B25="","",IFERROR(H25/G25,0)) | M25: =IF(B25="","",IFERROR(I25/H25,0)) | N25: =IF(B25="","",IFERROR(I25/K25,0)) | O25: =IF(B25="","",IFERROR(K25/I25,0)) | Q25: =IF(B25="","",B25&" | "&C25) | R25: =IF(B25="","",Q25&"#"&A25)
L26: =IF(B26="","",IFERROR(H26/G26,0)) | M26: =IF(B26="","",IFERROR(I26/H26,0)) | N26: =IF(B26="","",IFERROR(I26/K26,0)) | O26: =IF(B26="","",IFERROR(K26/I26,0)) | Q26: =IF(B26="","",B26&" | "&C26) | R26: =IF(B26="","",Q26&"#"&A26)
L27: =IF(B27="","",IFERROR(H27/G27,0)) | M27: =IF(B27="","",IFERROR(I27/H27,0)) | N27: =IF(B27="","",IFERROR(I27/K27,0)) | O27: =IF(B27="","",IFERROR(K27/I27,0)) | Q27: =IF(B27="","",B27&" | "&C27) | R27: =IF(B27="","",Q27&"#"&A27)
L28: =IF(B28="","",IFERROR(H28/G28,0)) | M28: =IF(B28="","",IFERROR(I28/H28,0)) | N28: =IF(B28="","",IFERROR(I28/K28,0)) | O28: =IF(B28="","",IFERROR(K28/I28,0)) | Q28: =IF(B28="","",B28&" | "&C28) | R28: =IF(B28="","",Q28&"#"&A28)
L29: =IF(B29="","",IFERROR(H29/G29,0)) | M29: =IF(B29="","",IFERROR(I29/H29,0)) | N29: =IF(B29="","",IFERROR(I29/K29,0)) | O29: =IF(B29="","",IFERROR(K29/I29,0)) | Q29: =IF(B29="","",B29&" | "&C29) | R29: =IF(B29="","",Q29&"#"&A29)
L30: =IF(B30="","",IFERROR(H30/G30,0)) | M30: =IF(B30="","",IFERROR(I30/H30,0)) | N30: =IF(B30="","",IFERROR(I30/K30,0)) | O30: =IF(B30="","",IFERROR(K30/I30,0)) | Q30: =IF(B30="","",B30&" | "&C30) | R30: =IF(B30="","",Q30&"#"&A30)
... L403: =IF(B403="","",IFERROR(H403/G403,0)) | M403: =IF(B403="","",IFERROR(I403/H403,0)) | N403: =IF(B403="","",IFERROR(I403/K403,0)) | O403: =IF(B403="","",IFERROR(K403/I403,0)) | Q403: =IF(B403="","",B403&" | "&C403) | R403: =IF(B403="","",Q403&"#"&A403)

Sheet Tickets
A1: Tickets — un ticket por cada cambio. 'Base' = acumulado en este grupo al aplicar el cambio; 'Después' = solo lo ocurrido desde entonces.
A3: Ticket | B3: Fecha creación | C3: Tipo de cambio | D3: Palabra clave | E3: Tipo de coincidencia | F3: Valor antes | G3: Valor después | H3: Cambio % | I3: Motivo / hipótesis | J3: ACOS de referencia | K3: Qué es la referencia | L3: Estado del ticket | M3: Fecha aplicado | N3: Revisar a partir de | O3: Base: Clics | P3: Base: Coste | Q3: Base: Compras | R3: Base: Ventas | S3: Después: Clics | T3: Después: Coste | U3: Después: Compras | V3: Después: Ventas | W3: Después: ACOS | X3: Veredicto | Y3: Notas
A4: T-001 | B4: 46290 | C4: Crear grupo de anuncios | H4: =IF(OR(F4="",G4="",F4=0),"",G4/F4-1) | I4: Crear 'Pinza - Principal V2' con el anuncio B0DCZS1NR6 (O8-5W7J-DSK1) y las 10 keywords de T-002…T-011. Objetivo: concentrar el gasto en lo que ya vende y en 5 frases nuevas con alta intención, con ACOS ≤ 35%. | L4: Pendiente de aplicar | N4: =IF(M4="","",M4+Leyenda!$B$15) | O4: 0 | P4: 0 | Q4: 0 | R4: 0 | S4: =IF(OR(D4="",M4=""),"",IFERROR(INDEX(Segmentación!$F$4:$F$18,MATCH(D4&" | "&E4,Segmentación!$W$4:$W$18,0))-O4,"")) | T4: =IF(OR(D4="",M4=""),"",IFERROR(INDEX(Segmentación!$H$4:$H$18,MATCH(D4&" | "&E4,Segmentación!$W$4:$W$18,0))-P4,"")) | U4: =IF(OR(D4="",M4=""),"",IFERROR(INDEX(Segmentación!$J$4:$J$18,MATCH(D4&" | "&E4,Segmentación!$W$4:$W$18,0))-Q4,"")) | V4: =IF(OR(D4="",M4=""),"",IFERROR(INDEX(Segmentación!$K$4:$K$18,MATCH(D4&" | "&E4,Segmentación!$W$4:$W$18,0))-R4,"")) | W4: =IF(OR(S4="",V4=""),"",IF(V4=0,"",T4/V4)) | X4: =IF(C4="","",IF(OR(D4="",ISNUMBER(SEARCH("negativa",C4))),IF(M4="","Pendiente de aplicar","Aplicado (no se evalúa)"),IF(M4="","Pendiente de aplicar",IF(S4="","Sin datos",IF(S4<Leyenda!$B$13,"Esperando datos ("&S4&" de 10 clics)",IF(U4=0,"Empeora: "&S4&" clics sin venta",IF(TODAY()<N4,"Esperando atribución (7 días)",IF(W4<=J4,"Mejora (ACOS "&TEXT(W4,"0%")&")","Empeora (ACOS "&TEXT(W4,"0%")&")")))))))) -> Pendiente de aplicar
A5: T-002 | B5: 46290 | C5: Añadir keyword (histórica) | D5: soporte móvil para coche con pinza | E5: Frase | F5: 0.62 | G5: 0.78 | H5: =IF(OR(F5="",G5="",F5=0),"",G5/F5-1) -> 0.25806452 | I5: Histórico (suma de 2 grupos): 27 clics, 6 compras, 12.36 € de gasto, 65.35 € de ventas. ACOS 18.9% < 30% → subir 25%. | J5: 0.1891 | K5: ACOS en el grupo antiguo | L5: Pendiente de aplicar | N5: =IF(M5="","",M5+Leyenda!$B$15) | O5: 0 | P5: 0 | Q5: 0 | R5: 0 | S5: =IF(OR(D5="",M5=""),"",IFERROR(INDEX(Segmentación!$F$4:$F$18,MATCH(D5&" | "&E5,Segmentación!$W$4:$W$18,0))-O5,"")) | T5: =IF(OR(D5="",M5=""),"",IFERROR(INDEX(Segmentación!$H$4:$H$18,MATCH(D5&" | "&E5,Segmentación!$W$4:$W$18,0))-P5,"")) | U5: =IF(OR(D5="",M5=""),"",IFERROR(INDEX(Segmentación!$J$4:$J$18,MATCH(D5&" | "&E5,Segmentación!$W$4:$W$18,0))-Q5,"")) | V5: =IF(OR(D5="",M5=""),"",IFERROR(INDEX(Segmentación!$K$4:$K$18,MATCH(D5&" | "&E5,Segmentación!$W$4:$W$18,0))-R5,"")) | W5: =IF(OR(S5="",V5=""),"",IF(V5=0,"",T5/V5)) | X5: =IF(C5="","",IF(OR(D5="",ISNUMBER(SEARCH("negativa",C5))),IF(M5="","Pendiente de aplicar","Aplicado (no se evalúa)"),IF(M5="","Pendiente de aplicar",IF(S5="","Sin datos",IF(S5<Leyenda!$B$13,"Esperando datos ("&S5&" de 10 clics)",IF(U5=0,"Empeora: "&S5&" clics sin venta",IF(TODAY()<N5,"Esperando atribución (7 días)",IF(W5<=J5,"Mejora (ACOS "&TEXT(W5,"0%")&")","Empeora (ACOS "&TEXT(W5,"0%")&")")))))))) -> Pendiente de aplicar
A6: T-003 | B6: 46290 | C6: Añadir keyword (histórica) | D6: soporte móvil para coche de pinza para salpicadero | E6: Amplia | F6: 0.3 | G6: 0.3 | H6: =IF(OR(F6="",G6="",F6=0),"",G6/F6-1) -> 0 | I6: Histórico: 9 clics, 1 compras, 3.12 € de gasto, 10.39 € de ventas. ACOS 30.0% en objetivo → se mantiene. | J6: 0.3003 | K6: ACOS en el grupo antiguo | L6: Pendiente de aplicar | N6: =IF(M6="","",M6+Leyenda!$B$15) | O6: 0 | P6: 0 | Q6: 0 | R6: 0 | S6: =IF(OR(D6="",M6=""),"",IFERROR(INDEX(Segmentación!$F$4:$F$18,MATCH(D6&" | "&E6,Segmentación!$W$4:$W$18,0))-O6,"")) | T6: =IF(OR(D6="",M6=""),"",IFERROR(INDEX(Segmentación!$H$4:$H$18,MATCH(D6&" | "&E6,Segmentación!$W$4:$W$18,0))-P6,"")) | U6: =IF(OR(D6="",M6=""),"",IFERROR(INDEX(Segmentación!$J$4:$J$18,MATCH(D6&" | "&E6,Segmentación!$W$4:$W$18,0))-Q6,"")) | V6: =IF(OR(D6="",M6=""),"",IFERROR(INDEX(Segmentación!$K$4:$K$18,MATCH(D6&" | "&E6,Segmentación!$W$4:$W$18,0))-R6,"")) | W6: =IF(OR(S6="",V6=""),"",IF(V6=0,"",T6/V6)) | X6: =IF(C6="","",IF(OR(D6="",ISNUMBER(SEARCH("negativa",C6))),IF(M6="","Pendiente de aplicar","Aplicado (no se evalúa)"),IF(M6="","Pendiente de aplicar",IF(S6="","Sin datos",IF(S6<Leyenda!$B$13,"Esperando datos ("&S6&" de 10 clics)",IF(U6=0,"Empeora: "&S6&" clics sin venta",IF(TODAY()<N6,"Esperando atribución (7 días)",IF(W6<=J6,"Mejora (ACOS "&TEXT(W6,"0%")&")","Empeora (ACOS "&TEXT(W6,"0%")&")")))))))) -> Pendiente de aplicar
A7: T-004 | B7: 46290 | C7: Añadir keyword (histórica) | D7: soporte móvil para coche de pinza | E7: Exacta | F7: 0.51 | G7: 0.51 | H7: =IF(OR(F7="",G7="",F7=0),"",G7/F7-1) -> 0 | I7: Histórico (suma de 2 grupos): 14 clics, 2 compras, 7.41 € de gasto, 23.98 € de ventas. ACOS 30.9% en objetivo → se mantiene. | J7: 0.309 | K7: ACOS en el grupo antiguo | L7: Pendiente de aplicar | N7: =IF(M7="","",M7+Leyenda!$B$15) | O7: 0 | P7: 0 | Q7: 0 | R7: 0 | S7: =IF(OR(D7="",M7=""),"",IFERROR(INDEX(Segmentación!$F$4:$F$18,MATCH(D7&" | "&E7,Segmentación!$W$4:$W$18,0))-O7,"")) | T7: =IF(OR(D7="",M7=""),"",IFERROR(INDEX(Segmentación!$H$4:$H$18,MATCH(D7&" | "&E7,Segmentación!$W$4:$W$18,0))-P7,"")) | U7: =IF(OR(D7="",M7=""),"",IFERROR(INDEX(Segmentación!$J$4:$J$18,MATCH(D7&" | "&E7,Segmentación!$W$4:$W$18,0))-Q7,"")) | V7: =IF(OR(D7="",M7=""),"",IFERROR(INDEX(Segmentación!$K$4:$K$18,MATCH(D7&" | "&E7,Segmentación!$W$4:$W$18,0))-R7,"")) | W7: =IF(OR(S7="",V7=""),"",IF(V7=0,"",T7/V7)) | X7: =IF(C7="","",IF(OR(D7="",ISNUMBER(SEARCH("negativa",C7))),IF(M7="","Pendiente de aplicar","Aplicado (no se evalúa)"),IF(M7="","Pendiente de aplicar",IF(S7="","Sin datos",IF(S7<Leyenda!$B$13,"Esperando datos ("&S7&" de 10 clics)",IF(U7=0,"Empeora: "&S7&" clics sin venta",IF(TODAY()<N7,"Esperando atribución (7 días)",IF(W7<=J7,"Mejora (ACOS "&TEXT(W7,"0%")&")","Empeora (ACOS "&TEXT(W7,"0%")&")")))))))) -> Pendiente de aplicar
A8: T-005 | B8: 46290 | C8: Añadir keyword (histórica) | D8: soporte móvil para coche de pinza | E8: Amplia | F8: 0.41 | G8: 0.41 | H8: =IF(OR(F8="",G8="",F8=0),"",G8/F8-1) -> 0 | I8: Histórico (suma de 2 grupos): 37 clics, 4 compras, 13.64 € de gasto, 43.16 € de ventas. ACOS 31.6% en objetivo → se mantiene (limitada a la puja máx. rentable 0.41€). | J8: 0.316 | K8: ACOS en el grupo antiguo | L8: Pendiente de aplicar | N8: =IF(M8="","",M8+Leyenda!$B$15) | O8: 0 | P8: 0 | Q8: 0 | R8: 0 | S8: =IF(OR(D8="",M8=""),"",IFERROR(INDEX(Segmentación!$F$4:$F$18,MATCH(D8&" | "&E8,Segmentación!$W$4:$W$18,0))-O8,"")) | T8: =IF(OR(D8="",M8=""),"",IFERROR(INDEX(Segmentación!$H$4:$H$18,MATCH(D8&" | "&E8,Segmentación!$W$4:$W$18,0))-P8,"")) | U8: =IF(OR(D8="",M8=""),"",IFERROR(INDEX(Segmentación!$J$4:$J$18,MATCH(D8&" | "&E8,Segmentación!$W$4:$W$18,0))-Q8,"")) | V8: =IF(OR(D8="",M8=""),"",IFERROR(INDEX(Segmentación!$K$4:$K$18,MATCH(D8&" | "&E8,Segmentación!$W$4:$W$18,0))-R8,"")) | W8: =IF(OR(S8="",V8=""),"",IF(V8=0,"",T8/V8)) | X8: =IF(C8="","",IF(OR(D8="",ISNUMBER(SEARCH("negativa",C8))),IF(M8="","Pendiente de aplicar","Aplicado (no se evalúa)"),IF(M8="","Pendiente de aplicar",IF(S8="","Sin datos",IF(S8<Leyenda!$B$13,"Esperando datos ("&S8&" de 10 clics)",IF(U8=0,"Empeora: "&S8&" clics sin venta",IF(TODAY()<N8,"Esperando atribución (7 días)",IF(W8<=J8,"Mejora (ACOS "&TEXT(W8,"0%")&")","Empeora (ACOS "&TEXT(W8,"0%")&")")))))))) -> Pendiente de aplicar
A9: T-006 | B9: 46290 | C9: Añadir keyword (histórica) | D9: soporte móvil para coche con pinza | E9: Amplia | F9: 0.55 | G9: 0.41 | H9: =IF(OR(F9="",G9="",F9=0),"",G9/F9-1) -> -0.25454545 | I9: Histórico: 18 clics, 2 compras, 10.83 € de gasto, 22.78 € de ventas. ACOS 47.5% > 40% → bajar 25%. | J9: 0.4754 | K9: ACOS en el grupo antiguo | L9: Pendiente de aplicar | N9: =IF(M9="","",M9+Leyenda!$B$15) | O9: 0 | P9: 0 | Q9: 0 | R9: 0 | S9: =IF(OR(D9="",M9=""),"",IFERROR(INDEX(Segmentación!$F$4:$F$18,MATCH(D9&" | "&E9,Segmentación!$W$4:$W$18,0))-O9,"")) | T9: =IF(OR(D9="",M9=""),"",IFERROR(INDEX(Segmentación!$H$4:$H$18,MATCH(D9&" | "&E9,Segmentación!$W$4:$W$18,0))-P9,"")) | U9: =IF(OR(D9="",M9=""),"",IFERROR(INDEX(Segmentación!$J$4:$J$18,MATCH(D9&" | "&E9,Segmentación!$W$4:$W$18,0))-Q9,"")) | V9: =IF(OR(D9="",M9=""),"",IFERROR(INDEX(Segmentación!$K$4:$K$18,MATCH(D9&" | "&E9,Segmentación!$W$4:$W$18,0))-R9,"")) | W9: =IF(OR(S9="",V9=""),"",IF(V9=0,"",T9/V9)) | X9: =IF(C9="","",IF(OR(D9="",ISNUMBER(SEARCH("negativa",C9))),IF(M9="","Pendiente de aplicar","Aplicado (no se evalúa)"),IF(M9="","Pendiente de aplicar",IF(S9="","Sin datos",IF(S9<Leyenda!$B$13,"Esperando datos ("&S9&" de 10 clics)",IF(U9=0,"Empeora: "&S9&" clics sin venta",IF(TODAY()<N9,"Esperando atribución (7 días)",IF(W9<=J9,"Mejora (ACOS "&TEXT(W9,"0%")&")","Empeora (ACOS "&TEXT(W9,"0%")&")")))))))) -> Pendiente de aplicar
A10: T-007 | B10: 46290 | C10: Añadir keyword (especial IA) | D10: soporte móvil coche pinza 360 | E10: Frase | G10: 0.44 | H10: =IF(OR(F10="",G10="",F10=0),"",G10/F10-1) | I10: Top del modelo con el histórico completo (11,4% compra/clic): junta 'pinza' + 'coche' (lo que más vende) con '360', una ventaja del título. Modelo: 11.3% compra/clic → puja máx. rentable 0.44 € para ACOS 35%. | J10: =Leyenda!$B$5 -> 0.35 | K10: ACOS objetivo | L10: Pendiente de aplicar | N10: =IF(M10="","",M10+Leyenda!$B$15) | O10: 0 | P10: 0 | Q10: 0 | R10: 0 | S10: =IF(OR(D10="",M10=""),"",IFERROR(INDEX(Segmentación!$F$4:$F$18,MATCH(D10&" | "&E10,Segmentación!$W$4:$W$18,0))-O10,"")) | T10: =IF(OR(D10="",M10=""),"",IFERROR(INDEX(Segmentación!$H$4:$H$18,MATCH(D10&" | "&E10,Segmentación!$W$4:$W$18,0))-P10,"")) | U10: =IF(OR(D10="",M10=""),"",IFERROR(INDEX(Segmentación!$J$4:$J$18,MATCH(D10&" | "&E10,Segmentación!$W$4:$W$18,0))-Q10,"")) | V10: =IF(OR(D10="",M10=""),"",IFERROR(INDEX(Segmentación!$K$4:$K$18,MATCH(D10&" | "&E10,Segmentación!$W$4:$W$18,0))-R10,"")) | W10: =IF(OR(S10="",V10=""),"",IF(V10=0,"",T10/V10)) | X10: =IF(C10="","",IF(OR(D10="",ISNUMBER(SEARCH("negativa",C10))),IF(M10="","Pendiente de aplicar","Aplicado (no se evalúa)"),IF(M10="","Pendiente de aplicar",IF(S10="","Sin datos",IF(S10<Leyenda!$B$13,"Esperando datos ("&S10&" de 10 clics)",IF(U10=0,"Empeora: "&S10&" clics sin venta",IF(TODAY()<N10,"Esperando atribución (7 días)",IF(W10<=J10,"Mejora (ACOS "&TEXT(W10,"0%")&")","Empeora (ACOS "&TEXT(W10,"0%")&")")))))))) -> Pendiente de aplicar
A11: T-008 | B11: 46290 | C11: Añadir keyword (especial IA) | D11: soporte móvil coche pinza para espejo retrovisor | E11: Frase | G11: 0.46 | H11: =IF(OR(F11="",G11="",F11=0),"",G11/F11-1) | I11: El retrovisor es uno de los 3 sitios de montaje del título y ninguna keyword lo cubre. Quien lo busca sabe exactamente qué quiere. Modelo: 11.7% compra/clic → puja máx. rentable 0.46 € para ACOS 35%. | J11: =Leyenda!$B$5 -> 0.35 | K11: ACOS objetivo | L11: Pendiente de aplicar | N11: =IF(M11="","",M11+Leyenda!$B$15) | O11: 0 | P11: 0 | Q11: 0 | R11: 0 | S11: =IF(OR(D11="",M11=""),"",IFERROR(INDEX(Segmentación!$F$4:$F$18,MATCH(D11&" | "&E11,Segmentación!$W$4:$W$18,0))-O11,"")) | T11: =IF(OR(D11="",M11=""),"",IFERROR(INDEX(Segmentación!$H$4:$H$18,MATCH(D11&" | "&E11,Segmentación!$W$4:$W$18,0))-P11,"")) | U11: =IF(OR(D11="",M11=""),"",IFERROR(INDEX(Segmentación!$J$4:$J$18,MATCH(D11&" | "&E11,Segmentación!$W$4:$W$18,0))-Q11,"")) | V11: =IF(OR(D11="",M11=""),"",IFERROR(INDEX(Segmentación!$K$4:$K$18,MATCH(D11&" | "&E11,Segmentación!$W$4:$W$18,0))-R11,"")) | W11: =IF(OR(S11="",V11=""),"",IF(V11=0,"",T11/V11)) | X11: =IF(C11="","",IF(OR(D11="",ISNUMBER(SEARCH("negativa",C11))),IF(M11="","Pendiente de aplicar","Aplicado (no se evalúa)"),IF(M11="","Pendiente de aplicar",IF(S11="","Sin datos",IF(S11<Leyenda!$B$13,"Esperando datos ("&S11&" de 10 clics)",IF(U11=0,"Empeora: "&S11&" clics sin venta",IF(TODAY()<N11,"Esperando atribución (7 días)",IF(W11<=J11,"Mejora (ACOS "&TEXT(W11,"0%")&")","Empeora (ACOS "&TEXT(W11,"0%")&")")))))))) -> Pendiente de aplicar
A12: T-009 | B12: 46290 | C12: Añadir keyword (especial IA) | D12: soporte móvil coche pinza para parasol | E12: Frase | G12: 0.45 | H12: =IF(OR(F12="",G12="",F12=0),"",G12/F12-1) | I12: El parasol es otro sitio de montaje del título, sin cubrir. Búsqueda muy específica: poca competencia, intención alta. Modelo: 11.4% compra/clic → puja máx. rentable 0.45 € para ACOS 35%. | J12: =Leyenda!$B$5 -> 0.35 | K12: ACOS objetivo | L12: Pendiente de aplicar | N12: =IF(M12="","",M12+Leyenda!$B$15) | O12: 0 | P12: 0 | Q12: 0 | R12: 0 | S12: =IF(OR(D12="",M12=""),"",IFERROR(INDEX(Segmentación!$F$4:$F$18,MATCH(D12&" | "&E12,Segmentación!$W$4:$W$18,0))-O12,"")) | T12: =IF(OR(D12="",M12=""),"",IFERROR(INDEX(Segmentación!$H$4:$H$18,MATCH(D12&" | "&E12,Segmentación!$W$4:$W$18,0))-P12,"")) | U12: =IF(OR(D12="",M12=""),"",IFERROR(INDEX(Segmentación!$J$4:$J$18,MATCH(D12&" | "&E12,Segmentación!$W$4:$W$18,0))-Q12,"")) | V12: =IF(OR(D12="",M12=""),"",IFERROR(INDEX(Segmentación!$K$4:$K$18,MATCH(D12&" | "&E12,Segmentación!$W$4:$W$18,0))-R12,"")) | W12: =IF(OR(S12="",V12=""),"",IF(V12=0,"",T12/V12)) | X12: =IF(C12="","",IF(OR(D12="",ISNUMBER(SEARCH("negativa",C12))),IF(M12="","Pendiente de aplicar","Aplicado (no se evalúa)"),IF(M12="","Pendiente de aplicar",IF(S12="","Sin datos",IF(S12<Leyenda!$B$13,"Esperando datos ("&S12&" de 10 clics)",IF(U12=0,"Empeora: "&S12&" clics sin venta",IF(TODAY()<N12,"Esperando atribución (7 días)",IF(W12<=J12,"Mejora (ACOS "&TEXT(W12,"0%")&")","Empeora (ACOS "&TEXT(W12,"0%")&")")))))))) -> Pendiente de aplicar
