Workbook

Sheet Leyenda
A1: Memoria de campañas FreshFinder (pinza + rejilla)
A2: Creada 26/09/2026 con crear_memoria.py a partir de FreshFinder_Amazon_Ads_historico.xlsx y keyword_ml.py
A4: PARÁMETROS
A5: ACOS objetivo | B5: 0.35 | C5: Confirmado por Juan.
A6: Presupuesto diario por campaña | B6: 7 | C6: Pedido por Juan (26/09/2026): 7 €/día en cada una de las 3 campañas.
A7: Nº de campañas en la cuenta | B7: 4 | C7: Todas las campañas activas de la cartera, no solo las de esta memoria.
A8: Gasto máximo posible al mes | B8: =B6*B7*30 -> 840 | C8: 21 €/día × 30 días. Coincide con el tope de la cartera.
A9: Tope mensual de la cartera | B9: 840 | C9: Límite duro de CLAUDE.md (630 €, Juan 26/09/2026). Amazon para TODAS las campañas al llegar aquí.
A10: Días hasta agotar la cartera | B10: =IFERROR(B9/(B6*B7),0) -> 30 | C10: Con 21 €/día, la cartera dura el mes entero.
A11: Días entre revisiones de puja | B11: 3 | C11: Pedido por Juan.
A12: Rango de puja sobre la original | B12: 0.5 | C12: Pedido por Juan: ±50%.
A13: Stop-loss: clics sin ventas | B13: 15 | C13: Propuesto; pendiente de confirmar.
A14: Clics mínimos para evaluar | B14: 10 | C14: Con menos clics es ruido.
A15: Días para evaluar un cambio | B15: 7 | C15: Sponsored Products atribuye ventas hasta 7 días después del clic.
A17: CÓMO USAR LA MEMORIA
A18: 1. Sube resultados/bulk_2026-09-26.xlsx en Amazon Ads → Operaciones en bloque. Crea las 3 campañas EN PAUSA. Revisa el informe de resultados de Amazon.
A19: 2. A mano: crea la cartera (T-001) y mete dentro las 3 campañas; añade la categoría de 'Pinza - Pruebas'. Activa las campañas cuando todo esté bien.
A20: 3. En 'Tickets' pon la 'Fecha aplicado' de cada ticket y cambia su estado a 'Aplicado'.
A21: 4. Cada 3 días: exporta Segmentación de cada campaña (rango DESDE LA CREACIÓN HASTA HOY) y copia una fila por keyword/ASIN en 'Seguimiento' (fecha, campaña, texto, coincidencia, puja, impresiones, clics, coste, compras, ventas).
A22: 5. 'Segmentación' muestra el estado de cada keyword como en Amazon, con acción sugerida y stop-loss. Cada cambio que hagas = ticket nuevo (con la 'Base' copiada de Segmentación).
A23: 6. Un ticket se evalúa a los 7 días y con ≥10 clics nuevos: 'Veredicto' dice Mejora/Empeora.
A24: 7. Cada 2 semanas: descarga Términos de búsqueda (Amazon solo guarda 65 días) → negativas y keywords nuevas; y mira el informe de Ubicación.
A26: COLORES
A27: Ejemplo | B27: Celda para rellenar (texto azul)
A28: Ejemplo | B28: Keyword histórica: ya vendió
A29: Ejemplo | B29: Keyword especial del modelo (mismas reglas que las históricas)
A30: Ejemplo | B30: Campaña de pruebas: ASIN de competencia o categoría
A32: AVISOS
A33: • Las campañas antiguas siguen en pausa: si se reactivan, sus keywords compiten con estas (tú contra ti).
A34: • Los anuncios solo salen con la OFERTA DESTACADA (Buy Box) y stock. 0 impresiones → mira eso antes de tocar pujas.
A35: • Los ASIN de competencia salen de una búsqueda web: comprueba en amazon.es que existen y son más caros o peor valorados que el tuyo.
A36: • Rejilla: el modelo casi no aprende de su histórico (mejora 0,4% sobre la media; casi todo eran búsquedas genéricas). Sus especiales van más a ciegas que las de la pinza.

Sheet Campañas
A1: Configuración de campañas (tal cual se crean en Amazon Ads)
A3: Campaña | B3: Grupo de anuncios | C3: Producto (ASIN) | D3: SKU | E3: Segmentación | F3: Presupuesto diario | G3: Estrategia de pujas | H3: Puja predet. grupo | I3: Ubicaciones | J3: Cartera | K3: Estado al crear | L3: Ticket medio (€) | M3: Nº segmentaciones | N3: Ticket
A4: Pou - Principal V2 | B4: Pou - Principal V2 | C4: B0CPHXXHRQ | D4: NN-8FIP-9ZZT | E4: Manual - Palabras clave | F4: =Leyenda!$B$6 -> 7 | G4: Pujas dinámicas: solo reducir | H4: 0.3 | I4: 0% en las 3 (revisar a las 2 semanas) | J4: FreshFinder - cartera | K4: En pausa | L4: 11.99 | M4: 10

Sheet Segmentación
A1: Segmentación — mismas columnas que el export de Amazon Ads. Se actualiza sola desde 'Seguimiento'.
A3: Campaña | B3: Estado | C3: Palabra clave / segmentación | D3: Tipo de coincidencia | E3: Puja (EUR) | F3: Impresiones | G3: Clics | H3: CTR | I3: Coste total (EUR) | J3: CPC (EUR) | K3: Compras | L3: Ventas (EUR) | M3: ACOS | N3: ROAS | O3: Origen | P3: Puja original | Q3: Puja mín. -50% | R3: Puja máx. +50% | S3: Puja máx. rentable | T3: Ticket | U3: Última foto | V3: Stop-loss | W3: Acción sugerida | X3: Clave
A4: Pou - Principal V2 | B4: =IFERROR(INDEX(Seguimiento!$E:$E,MATCH(X4&"#"&_xlfn.MAXIFS(Seguimiento!$A:$A,Seguimiento!$R:$R,X4),Seguimiento!$S:$S,0)),"Activado") -> En pausa | C4: peluches de pou | D4: Amplia | E4: =IFERROR(IF(_xlfn.MAXIFS(Seguimiento!$A:$A,Seguimiento!$R:$R,X4)=0,P4,SUMIFS(Seguimiento!$G:$G,Seguimiento!$R:$R,X4,Seguimiento!$A:$A,_xlfn.MAXIFS(Seguimiento!$A:$A,Seguimiento!$R:$R,X4))),P4) -> 0.12 | F4: =IFERROR(SUMIFS(Seguimiento!$H:$H,Seguimiento!$R:$R,X4,Seguimiento!$A:$A,_xlfn.MAXIFS(Seguimiento!$A:$A,Seguimiento!$R:$R,X4)),0) -> 0 | G4: =IFERROR(SUMIFS(Seguimiento!$I:$I,Seguimiento!$R:$R,X4,Seguimiento!$A:$A,_xlfn.MAXIFS(Seguimiento!$A:$A,Seguimiento!$R:$R,X4)),0) -> 0 | H4: =IFERROR(G4/F4,0) -> 0 | I4: =IFERROR(SUMIFS(Seguimiento!$J:$J,Seguimiento!$R:$R,X4,Seguimiento!$A:$A,_xlfn.MAXIFS(Seguimiento!$A:$A,Seguimiento!$R:$R,X4)),0) -> 0 | J4: =IFERROR(I4/G4,0) -> 0 | K4: =IFERROR(SUMIFS(Seguimiento!$K:$K,Seguimiento!$R:$R,X4,Seguimiento!$A:$A,_xlfn.MAXIFS(Seguimiento!$A:$A,Seguimiento!$R:$R,X4)),0) -> 0 | L4: =IFERROR(SUMIFS(Seguimiento!$L:$L,Seguimiento!$R:$R,X4,Seguimiento!$A:$A,_xlfn.MAXIFS(Seguimiento!$A:$A,Seguimiento!$R:$R,X4)),0) -> 0 | M4: =IFERROR(I4/L4,0) -> 0 | N4: =IFERROR(L4/I4,0) -> 0 | O4: Histórica | P4: 0.12 | Q4: =ROUND(P4*(1-Leyenda!$B$12),2) -> 0.06 | R4: =ROUND(P4*(1+Leyenda!$B$12),2) -> 0.18 | S4: 0.12 | T4: T-003 | U4: =IFERROR(IF(_xlfn.MAXIFS(Seguimiento!$A:$A,Seguimiento!$R:$R,X4)=0,"",_xlfn.MAXIFS(Seguimiento!$A:$A,Seguimiento!$R:$R,X4)),"") -> 46291 | V4: =IF(AND(G4>=Leyenda!$B$13,K4=0),"PAUSAR (≥15 clics sin venta)",IF(AND(E4<=Q4,G4>=20,M4>0.5),"PAUSAR (puja mínima y ACOS>50%)","")) | W4: =IF(LEFT(V4,6)="PAUSAR","Pausar y crear ticket",IF(G4<Leyenda!$B$14,"Esperar (menos de 10 clics)",IF(K4=0,"Sin ventas aún: vigilar",IF(M4<0.3,"Subir 10-25% (máx. "&TEXT(MIN(R4,S4),"0.00")&" €)",IF(M4<=Leyenda!$B$5,"En objetivo: no tocar",IF(M4<=0.5,"Bajar 10-25% (mín. "&TEXT(Q4,"0.00")&" €)","Bajar 25-50% (mín. "&TEXT(Q4,"0.00")&" €)")))))) -> Esperar (menos de 10 clics) | X4: =A4&" | "&C4&" | "&D4 -> Pou - Principal V2 | peluches de pou | Amplia
A5: Pou - Principal V2 | B5: =IFERROR(INDEX(Seguimiento!$E:$E,MATCH(X5&"#"&_xlfn.MAXIFS(Seguimiento!$A:$A,Seguimiento!$R:$R,X5),Seguimiento!$S:$S,0)),"Activado") -> En pausa | C5: peluche pou | D5: Frase | E5: =IFERROR(IF(_xlfn.MAXIFS(Seguimiento!$A:$A,Seguimiento!$R:$R,X5)=0,P5,SUMIFS(Seguimiento!$G:$G,Seguimiento!$R:$R,X5,Seguimiento!$A:$A,_xlfn.MAXIFS(Seguimiento!$A:$A,Seguimiento!$R:$R,X5))),P5) -> 0.24 | F5: =IFERROR(SUMIFS(Seguimiento!$H:$H,Seguimiento!$R:$R,X5,Seguimiento!$A:$A,_xlfn.MAXIFS(Seguimiento!$A:$A,Seguimiento!$R:$R,X5)),0) -> 0 | G5: =IFERROR(SUMIFS(Seguimiento!$I:$I,Seguimiento!$R:$R,X5,Seguimiento!$A:$A,_xlfn.MAXIFS(Seguimiento!$A:$A,Seguimiento!$R:$R,X5)),0) -> 0 | H5: =IFERROR(G5/F5,0) -> 0 | I5: =IFERROR(SUMIFS(Seguimiento!$J:$J,Seguimiento!$R:$R,X5,Seguimiento!$A:$A,_xlfn.MAXIFS(Seguimiento!$A:$A,Seguimiento!$R:$R,X5)),0) -> 0 | J5: =IFERROR(I5/G5,0) -> 0 | K5: =IFERROR(SUMIFS(Seguimiento!$K:$K,Seguimiento!$R:$R,X5,Seguimiento!$A:$A,_xlfn.MAXIFS(Seguimiento!$A:$A,Seguimiento!$R:$R,X5)),0) -> 0 | L5: =IFERROR(SUMIFS(Seguimiento!$L:$L,Seguimiento!$R:$R,X5,Seguimiento!$A:$A,_xlfn.MAXIFS(Seguimiento!$A:$A,Seguimiento!$R:$R,X5)),0) -> 0 | M5: =IFERROR(I5/L5,0) -> 0 | N5: =IFERROR(L5/I5,0) -> 0 | O5: Especial IA | P5: 0.24 | Q5: =ROUND(P5*(1-Leyenda!$B$12),2) -> 0.12 | R5: =ROUND(P5*(1+Leyenda!$B$12),2) -> 0.36 | S5: 0.24 | T5: T-004 | U5: =IFERROR(IF(_xlfn.MAXIFS(Seguimiento!$A:$A,Seguimiento!$R:$R,X5)=0,"",_xlfn.MAXIFS(Seguimiento!$A:$A,Seguimiento!$R:$R,X5)),"") -> 46291 | V5: =IF(AND(G5>=Leyenda!$B$13,K5=0),"PAUSAR (≥15 clics sin venta)",IF(AND(E5<=Q5,G5>=20,M5>0.5),"PAUSAR (puja mínima y ACOS>50%)","")) | W5: =IF(LEFT(V5,6)="PAUSAR","Pausar y crear ticket",IF(G5<Leyenda!$B$14,"Esperar (menos de 10 clics)",IF(K5=0,"Sin ventas aún: vigilar",IF(M5<0.3,"Subir 10-25% (máx. "&TEXT(MIN(R5,S5),"0.00")&" €)",IF(M5<=Leyenda!$B$5,"En objetivo: no tocar",IF(M5<=0.5,"Bajar 10-25% (mín. "&TEXT(Q5,"0.00")&" €)","Bajar 25-50% (mín. "&TEXT(Q5,"0.00")&" €)")))))) -> Esperar (menos de 10 clics) | X5: =A5&" | "&C5&" | "&D5 -> Pou - Principal V2 | peluche pou | Frase
A6: Pou - Principal V2 | B6: =IFERROR(INDEX(Seguimiento!$E:$E,MATCH(X6&"#"&_xlfn.MAXIFS(Seguimiento!$A:$A,Seguimiento!$R:$R,X6),Seguimiento!$S:$S,0)),"Activado") -> En pausa | C6: muñeco pou | D6: Frase | E6: =IFERROR(IF(_xlfn.MAXIFS(Seguimiento!$A:$A,Seguimiento!$R:$R,X6)=0,P6,SUMIFS(Seguimiento!$G:$G,Seguimiento!$R:$R,X6,Seguimiento!$A:$A,_xlfn.MAXIFS(Seguimiento!$A:$A,Seguimiento!$R:$R,X6))),P6) -> 0.29 | F6: =IFERROR(SUMIFS(Seguimiento!$H:$H,Seguimiento!$R:$R,X6,Seguimiento!$A:$A,_xlfn.MAXIFS(Seguimiento!$A:$A,Seguimiento!$R:$R,X6)),0) -> 0 | G6: =IFERROR(SUMIFS(Seguimiento!$I:$I,Seguimiento!$R:$R,X6,Seguimiento!$A:$A,_xlfn.MAXIFS(Seguimiento!$A:$A,Seguimiento!$R:$R,X6)),0) -> 0 | H6: =IFERROR(G6/F6,0) -> 0 | I6: =IFERROR(SUMIFS(Seguimiento!$J:$J,Seguimiento!$R:$R,X6,Seguimiento!$A:$A,_xlfn.MAXIFS(Seguimiento!$A:$A,Seguimiento!$R:$R,X6)),0) -> 0 | J6: =IFERROR(I6/G6,0) -> 0 | K6: =IFERROR(SUMIFS(Seguimiento!$K:$K,Seguimiento!$R:$R,X6,Seguimiento!$A:$A,_xlfn.MAXIFS(Seguimiento!$A:$A,Seguimiento!$R:$R,X6)),0) -> 0 | L6: =IFERROR(SUMIFS(Seguimiento!$L:$L,Seguimiento!$R:$R,X6,Seguimiento!$A:$A,_xlfn.MAXIFS(Seguimiento!$A:$A,Seguimiento!$R:$R,X6)),0) -> 0 | M6: =IFERROR(I6/L6,0) -> 0 | N6: =IFERROR(L6/I6,0) -> 0 | O6: Especial IA | P6: 0.29 | Q6: =ROUND(P6*(1-Leyenda!$B$12),2) -> 0.15 | R6: =ROUND(P6*(1+Leyenda!$B$12),2) -> 0.44 | S6: 0.29 | T6: T-005 | U6: =IFERROR(IF(_xlfn.MAXIFS(Seguimiento!$A:$A,Seguimiento!$R:$R,X6)=0,"",_xlfn.MAXIFS(Seguimiento!$A:$A,Seguimiento!$R:$R,X6)),"") -> 46291 | V6: =IF(AND(G6>=Leyenda!$B$13,K6=0),"PAUSAR (≥15 clics sin venta)",IF(AND(E6<=Q6,G6>=20,M6>0.5),"PAUSAR (puja mínima y ACOS>50%)","")) | W6: =IF(LEFT(V6,6)="PAUSAR","Pausar y crear ticket",IF(G6<Leyenda!$B$14,"Esperar (menos de 10 clics)",IF(K6=0,"Sin ventas aún: vigilar",IF(M6<0.3,"Subir 10-25% (máx. "&TEXT(MIN(R6,S6),"0.00")&" €)",IF(M6<=Leyenda!$B$5,"En objetivo: no tocar",IF(M6<=0.5,"Bajar 10-25% (mín. "&TEXT(Q6,"0.00")&" €)","Bajar 25-50% (mín. "&TEXT(Q6,"0.00")&" €)")))))) -> Esperar (menos de 10 clics) | X6: =A6&" | "&C6&" | "&D6 -> Pou - Principal V2 | muñeco pou | Frase
A7: Pou - Principal V2 | B7: =IFERROR(INDEX(Seguimiento!$E:$E,MATCH(X7&"#"&_xlfn.MAXIFS(Seguimiento!$A:$A,Seguimiento!$R:$R,X7),Seguimiento!$S:$S,0)),"Activado") -> En pausa | C7: muñeco de peluche pou | D7: Frase | E7: =IFERROR(IF(_xlfn.MAXIFS(Seguimiento!$A:$A,Seguimiento!$R:$R,X7)=0,P7,SUMIFS(Seguimiento!$G:$G,Seguimiento!$R:$R,X7,Seguimiento!$A:$A,_xlfn.MAXIFS(Seguimiento!$A:$A,Seguimiento!$R:$R,X7))),P7) -> 0.24 | F7: =IFERROR(SUMIFS(Seguimiento!$H:$H,Seguimiento!$R:$R,X7,Seguimiento!$A:$A,_xlfn.MAXIFS(Seguimiento!$A:$A,Seguimiento!$R:$R,X7)),0) -> 0 | G7: =IFERROR(SUMIFS(Seguimiento!$I:$I,Seguimiento!$R:$R,X7,Seguimiento!$A:$A,_xlfn.MAXIFS(Seguimiento!$A:$A,Seguimiento!$R:$R,X7)),0) -> 0 | H7: =IFERROR(G7/F7,0) -> 0 | I7: =IFERROR(SUMIFS(Seguimiento!$J:$J,Seguimiento!$R:$R,X7,Seguimiento!$A:$A,_xlfn.MAXIFS(Seguimiento!$A:$A,Seguimiento!$R:$R,X7)),0) -> 0 | J7: =IFERROR(I7/G7,0) -> 0 | K7: =IFERROR(SUMIFS(Seguimiento!$K:$K,Seguimiento!$R:$R,X7,Seguimiento!$A:$A,_xlfn.MAXIFS(Seguimiento!$A:$A,Seguimiento!$R:$R,X7)),0) -> 0 | L7: =IFERROR(SUMIFS(Seguimiento!$L:$L,Seguimiento!$R:$R,X7,Seguimiento!$A:$A,_xlfn.MAXIFS(Seguimiento!$A:$A,Seguimiento!$R:$R,X7)),0) -> 0 | M7: =IFERROR(I7/L7,0) -> 0 | N7: =IFERROR(L7/I7,0) -> 0 | O7: Especial IA | P7: 0.24 | Q7: =ROUND(P7*(1-Leyenda!$B$12),2) -> 0.12 | R7: =ROUND(P7*(1+Leyenda!$B$12),2) -> 0.36 | S7: 0.24 | T7: T-006 | U7: =IFERROR(IF(_xlfn.MAXIFS(Seguimiento!$A:$A,Seguimiento!$R:$R,X7)=0,"",_xlfn.MAXIFS(Seguimiento!$A:$A,Seguimiento!$R:$R,X7)),"") -> 46291 | V7: =IF(AND(G7>=Leyenda!$B$13,K7=0),"PAUSAR (≥15 clics sin venta)",IF(AND(E7<=Q7,G7>=20,M7>0.5),"PAUSAR (puja mínima y ACOS>50%)","")) | W7: =IF(LEFT(V7,6)="PAUSAR","Pausar y crear ticket",IF(G7<Leyenda!$B$14,"Esperar (menos de 10 clics)",IF(K7=0,"Sin ventas aún: vigilar",IF(M7<0.3,"Subir 10-25% (máx. "&TEXT(MIN(R7,S7),"0.00")&" €)",IF(M7<=Leyenda!$B$5,"En objetivo: no tocar",IF(M7<=0.5,"Bajar 10-25% (mín. "&TEXT(Q7,"0.00")&" €)","Bajar 25-50% (mín. "&TEXT(Q7,"0.00")&" €)")))))) -> Esperar (menos de 10 clics) | X7: =A7&" | "&C7&" | "&D7 -> Pou - Principal V2 | muñeco de peluche pou | Frase
A8: Pou - Principal V2 | B8: =IFERROR(INDEX(Seguimiento!$E:$E,MATCH(X8&"#"&_xlfn.MAXIFS(Seguimiento!$A:$A,Seguimiento!$R:$R,X8),Seguimiento!$S:$S,0)),"Activado") -> En pausa | C8: alien pou | D8: Frase | E8: =IFERROR(IF(_xlfn.MAXIFS(Seguimiento!$A:$A,Seguimiento!$R:$R,X8)=0,P8,SUMIFS(Seguimiento!$G:$G,Seguimiento!$R:$R,X8,Seguimiento!$A:$A,_xlfn.MAXIFS(Seguimiento!$A:$A,Seguimiento!$R:$R,X8))),P8) -> 0.29 | F8: =IFERROR(SUMIFS(Seguimiento!$H:$H,Seguimiento!$R:$R,X8,Seguimiento!$A:$A,_xlfn.MAXIFS(Seguimiento!$A:$A,Seguimiento!$R:$R,X8)),0) -> 0 | G8: =IFERROR(SUMIFS(Seguimiento!$I:$I,Seguimiento!$R:$R,X8,Seguimiento!$A:$A,_xlfn.MAXIFS(Seguimiento!$A:$A,Seguimiento!$R:$R,X8)),0) -> 0 | H8: =IFERROR(G8/F8,0) -> 0 | I8: =IFERROR(SUMIFS(Seguimiento!$J:$J,Seguimiento!$R:$R,X8,Seguimiento!$A:$A,_xlfn.MAXIFS(Seguimiento!$A:$A,Seguimiento!$R:$R,X8)),0) -> 0 | J8: =IFERROR(I8/G8,0) -> 0 | K8: =IFERROR(SUMIFS(Seguimiento!$K:$K,Seguimiento!$R:$R,X8,Seguimiento!$A:$A,_xlfn.MAXIFS(Seguimiento!$A:$A,Seguimiento!$R:$R,X8)),0) -> 0 | L8: =IFERROR(SUMIFS(Seguimiento!$L:$L,Seguimiento!$R:$R,X8,Seguimiento!$A:$A,_xlfn.MAXIFS(Seguimiento!$A:$A,Seguimiento!$R:$R,X8)),0) -> 0 | M8: =IFERROR(I8/L8,0) -> 0 | N8: =IFERROR(L8/I8,0) -> 0 | O8: Especial IA | P8: 0.29 | Q8: =ROUND(P8*(1-Leyenda!$B$12),2) -> 0.15 | R8: =ROUND(P8*(1+Leyenda!$B$12),2) -> 0.44 | S8: 0.29 | T8: T-007 | U8: =IFERROR(IF(_xlfn.MAXIFS(Seguimiento!$A:$A,Seguimiento!$R:$R,X8)=0,"",_xlfn.MAXIFS(Seguimiento!$A:$A,Seguimiento!$R:$R,X8)),"") -> 46291 | V8: =IF(AND(G8>=Leyenda!$B$13,K8=0),"PAUSAR (≥15 clics sin venta)",IF(AND(E8<=Q8,G8>=20,M8>0.5),"PAUSAR (puja mínima y ACOS>50%)","")) | W8: =IF(LEFT(V8,6)="PAUSAR","Pausar y crear ticket",IF(G8<Leyenda!$B$14,"Esperar (menos de 10 clics)",IF(K8=0,"Sin ventas aún: vigilar",IF(M8<0.3,"Subir 10-25% (máx. "&TEXT(MIN(R8,S8),"0.00")&" €)",IF(M8<=Leyenda!$B$5,"En objetivo: no tocar",IF(M8<=0.5,"Bajar 10-25% (mín. "&TEXT(Q8,"0.00")&" €)","Bajar 25-50% (mín. "&TEXT(Q8,"0.00")&" €)")))))) -> Esperar (menos de 10 clics) | X8: =A8&" | "&C8&" | "&D8 -> Pou - Principal V2 | alien pou | Frase
A9: Pou - Principal V2 | B9: =IFERROR(INDEX(Seguimiento!$E:$E,MATCH(X9&"#"&_xlfn.MAXIFS(Seguimiento!$A:$A,Seguimiento!$R:$R,X9),Seguimiento!$S:$S,0)),"Activado") -> En pausa | C9: peluche pou alienígena | D9: Frase | E9: =IFERROR(IF(_xlfn.MAXIFS(Seguimiento!$A:$A,Seguimiento!$R:$R,X9)=0,P9,SUMIFS(Seguimiento!$G:$G,Seguimiento!$R:$R,X9,Seguimiento!$A:$A,_xlfn.MAXIFS(Seguimiento!$A:$A,Seguimiento!$R:$R,X9))),P9) -> 0.24 | F9: =IFERROR(SUMIFS(Seguimiento!$H:$H,Seguimiento!$R:$R,X9,Seguimiento!$A:$A,_xlfn.MAXIFS(Seguimiento!$A:$A,Seguimiento!$R:$R,X9)),0) -> 0 | G9: =IFERROR(SUMIFS(Seguimiento!$I:$I,Seguimiento!$R:$R,X9,Seguimiento!$A:$A,_xlfn.MAXIFS(Seguimiento!$A:$A,Seguimiento!$R:$R,X9)),0) -> 0 | H9: =IFERROR(G9/F9,0) -> 0 | I9: =IFERROR(SUMIFS(Seguimiento!$J:$J,Seguimiento!$R:$R,X9,Seguimiento!$A:$A,_xlfn.MAXIFS(Seguimiento!$A:$A,Seguimiento!$R:$R,X9)),0) -> 0 | J9: =IFERROR(I9/G9,0) -> 0 | K9: =IFERROR(SUMIFS(Seguimiento!$K:$K,Seguimiento!$R:$R,X9,Seguimiento!$A:$A,_xlfn.MAXIFS(Seguimiento!$A:$A,Seguimiento!$R:$R,X9)),0) -> 0 | L9: =IFERROR(SUMIFS(Seguimiento!$L:$L,Seguimiento!$R:$R,X9,Seguimiento!$A:$A,_xlfn.MAXIFS(Seguimiento!$A:$A,Seguimiento!$R:$R,X9)),0) -> 0 | M9: =IFERROR(I9/L9,0) -> 0 | N9: =IFERROR(L9/I9,0) -> 0 | O9: Especial IA | P9: 0.24 | Q9: =ROUND(P9*(1-Leyenda!$B$12),2) -> 0.12 | R9: =ROUND(P9*(1+Leyenda!$B$12),2) -> 0.36 | S9: 0.24 | T9: T-008 | U9: =IFERROR(IF(_xlfn.MAXIFS(Seguimiento!$A:$A,Seguimiento!$R:$R,X9)=0,"",_xlfn.MAXIFS(Seguimiento!$A:$A,Seguimiento!$R:$R,X9)),"") -> 46291 | V9: =IF(AND(G9>=Leyenda!$B$13,K9=0),"PAUSAR (≥15 clics sin venta)",IF(AND(E9<=Q9,G9>=20,M9>0.5),"PAUSAR (puja mínima y ACOS>50%)","")) | W9: =IF(LEFT(V9,6)="PAUSAR","Pausar y crear ticket",IF(G9<Leyenda!$B$14,"Esperar (menos de 10 clics)",IF(K9=0,"Sin ventas aún: vigilar",IF(M9<0.3,"Subir 10-25% (máx. "&TEXT(MIN(R9,S9),"0.00")&" €)",IF(M9<=Leyenda!$B$5,"En objetivo: no tocar",IF(M9<=0.5,"Bajar 10-25% (mín. "&TEXT(Q9,"0.00")&" €)","Bajar 25-50% (mín. "&TEXT(Q9,"0.00")&" €)")))))) -> Esperar (menos de 10 clics) | X9: =A9&" | "&C9&" | "&D9 -> Pou - Principal V2 | peluche pou alienígena | Frase
A10: Pou - Principal V2 | B10: =IFERROR(INDEX(Seguimiento!$E:$E,MATCH(X10&"#"&_xlfn.MAXIFS(Seguimiento!$A:$A,Seguimiento!$R:$R,X10),Seguimiento!$S:$S,0)),"Activado") -> En pausa | C10: peluche pou 22 cm | D10: Frase | E10: =IFERROR(IF(_xlfn.MAXIFS(Seguimiento!$A:$A,Seguimiento!$R:$R,X10)=0,P10,SUMIFS(Seguimiento!$G:$G,Seguimiento!$R:$R,X10,Seguimiento!$A:$A,_xlfn.MAXIFS(Seguimiento!$A:$A,Seguimiento!$R:$R,X10))),P10) -> 0.25 | F10: =IFERROR(SUMIFS(Seguimiento!$H:$H,Seguimiento!$R:$R,X10,Seguimiento!$A:$A,_xlfn.MAXIFS(Seguimiento!$A:$A,Seguimiento!$R:$R,X10)),0) -> 0 | G10: =IFERROR(SUMIFS(Seguimiento!$I:$I,Seguimiento!$R:$R,X10,Seguimiento!$A:$A,_xlfn.MAXIFS(Seguimiento!$A:$A,Seguimiento!$R:$R,X10)),0) -> 0 | H10: =IFERROR(G10/F10,0) -> 0 | I10: =IFERROR(SUMIFS(Seguimiento!$J:$J,Seguimiento!$R:$R,X10,Seguimiento!$A:$A,_xlfn.MAXIFS(Seguimiento!$A:$A,Seguimiento!$R:$R,X10)),0) -> 0 | J10: =IFERROR(I10/G10,0) -> 0 | K10: =IFERROR(SUMIFS(Seguimiento!$K:$K,Seguimiento!$R:$R,X10,Seguimiento!$A:$A,_xlfn.MAXIFS(Seguimiento!$A:$A,Seguimiento!$R:$R,X10)),0) -> 0 | L10: =IFERROR(SUMIFS(Seguimiento!$L:$L,Seguimiento!$R:$R,X10,Seguimiento!$A:$A,_xlfn.MAXIFS(Seguimiento!$A:$A,Seguimiento!$R:$R,X10)),0) -> 0 | M10: =IFERROR(I10/L10,0) -> 0 | N10: =IFERROR(L10/I10,0) -> 0 | O10: Especial IA | P10: 0.25 | Q10: =ROUND(P10*(1-Leyenda!$B$12),2) -> 0.13 | R10: =ROUND(P10*(1+Leyenda!$B$12),2) -> 0.38 | S10: 0.25 | T10: T-009 | U10: =IFERROR(IF(_xlfn.MAXIFS(Seguimiento!$A:$A,Seguimiento!$R:$R,X10)=0,"",_xlfn.MAXIFS(Seguimiento!$A:$A,Seguimiento!$R:$R,X10)),"") -> 46291 | V10: =IF(AND(G10>=Leyenda!$B$13,K10=0),"PAUSAR (≥15 clics sin venta)",IF(AND(E10<=Q10,G10>=20,M10>0.5),"PAUSAR (puja mínima y ACOS>50%)","")) | W10: =IF(LEFT(V10,6)="PAUSAR","Pausar y crear ticket",IF(G10<Leyenda!$B$14,"Esperar (menos de 10 clics)",IF(K10=0,"Sin ventas aún: vigilar",IF(M10<0.3,"Subir 10-25% (máx. "&TEXT(MIN(R10,S10),"0.00")&" €)",IF(M10<=Leyenda!$B$5,"En objetivo: no tocar",IF(M10<=0.5,"Bajar 10-25% (mín. "&TEXT(Q10,"0.00")&" €)","Bajar 25-50% (mín. "&TEXT(Q10,"0.00")&" €)")))))) -> Esperar (menos de 10 clics) | X10: =A10&" | "&C10&" | "&D10 -> Pou - Principal V2 | peluche pou 22 cm | Frase
A11: Pou - Principal V2 | B11: =IFERROR(INDEX(Seguimiento!$E:$E,MATCH(X11&"#"&_xlfn.MAXIFS(Seguimiento!$A:$A,Seguimiento!$R:$R,X11),Seguimiento!$S:$S,0)),"Activado") -> En pausa | C11: peluche pou regalo | D11: Frase | E11: =IFERROR(IF(_xlfn.MAXIFS(Seguimiento!$A:$A,Seguimiento!$R:$R,X11)=0,P11,SUMIFS(Seguimiento!$G:$G,Seguimiento!$R:$R,X11,Seguimiento!$A:$A,_xlfn.MAXIFS(Seguimiento!$A:$A,Seguimiento!$R:$R,X11))),P11) -> 0.24 | F11: =IFERROR(SUMIFS(Seguimiento!$H:$H,Seguimiento!$R:$R,X11,Seguimiento!$A:$A,_xlfn.MAXIFS(Seguimiento!$A:$A,Seguimiento!$R:$R,X11)),0) -> 0 | G11: =IFERROR(SUMIFS(Seguimiento!$I:$I,Seguimiento!$R:$R,X11,Seguimiento!$A:$A,_xlfn.MAXIFS(Seguimiento!$A:$A,Seguimiento!$R:$R,X11)),0) -> 0 | H11: =IFERROR(G11/F11,0) -> 0 | I11: =IFERROR(SUMIFS(Seguimiento!$J:$J,Seguimiento!$R:$R,X11,Seguimiento!$A:$A,_xlfn.MAXIFS(Seguimiento!$A:$A,Seguimiento!$R:$R,X11)),0) -> 0 | J11: =IFERROR(I11/G11,0) -> 0 | K11: =IFERROR(SUMIFS(Seguimiento!$K:$K,Seguimiento!$R:$R,X11,Seguimiento!$A:$A,_xlfn.MAXIFS(Seguimiento!$A:$A,Seguimiento!$R:$R,X11)),0) -> 0 | L11: =IFERROR(SUMIFS(Seguimiento!$L:$L,Seguimiento!$R:$R,X11,Seguimiento!$A:$A,_xlfn.MAXIFS(Seguimiento!$A:$A,Seguimiento!$R:$R,X11)),0) -> 0 | M11: =IFERROR(I11/L11,0) -> 0 | N11: =IFERROR(L11/I11,0) -> 0 | O11: Especial IA | P11: 0.24 | Q11: =ROUND(P11*(1-Leyenda!$B$12),2) -> 0.12 | R11: =ROUND(P11*(1+Leyenda!$B$12),2) -> 0.36 | S11: 0.24 | T11: T-010 | U11: =IFERROR(IF(_xlfn.MAXIFS(Seguimiento!$A:$A,Seguimiento!$R:$R,X11)=0,"",_xlfn.MAXIFS(Seguimiento!$A:$A,Seguimiento!$R:$R,X11)),"") -> 46291 | V11: =IF(AND(G11>=Leyenda!$B$13,K11=0),"PAUSAR (≥15 clics sin venta)",IF(AND(E11<=Q11,G11>=20,M11>0.5),"PAUSAR (puja mínima y ACOS>50%)","")) | W11: =IF(LEFT(V11,6)="PAUSAR","Pausar y crear ticket",IF(G11<Leyenda!$B$14,"Esperar (menos de 10 clics)",IF(K11=0,"Sin ventas aún: vigilar",IF(M11<0.3,"Subir 10-25% (máx. "&TEXT(MIN(R11,S11),"0.00")&" €)",IF(M11<=Leyenda!$B$5,"En objetivo: no tocar",IF(M11<=0.5,"Bajar 10-25% (mín. "&TEXT(Q11,"0.00")&" €)","Bajar 25-50% (mín. "&TEXT(Q11,"0.00")&" €)")))))) -> Esperar (menos de 10 clics) | X11: =A11&" | "&C11&" | "&D11 -> Pou - Principal V2 | peluche pou regalo | Frase
A12: Pou - Principal V2 | B12: =IFERROR(INDEX(Seguimiento!$E:$E,MATCH(X12&"#"&_xlfn.MAXIFS(Seguimiento!$A:$A,Seguimiento!$R:$R,X12),Seguimiento!$S:$S,0)),"Activado") -> En pausa | C12: muñeco pou regalo niño | D12: Frase | E12: =IFERROR(IF(_xlfn.MAXIFS(Seguimiento!$A:$A,Seguimiento!$R:$R,X12)=0,P12,SUMIFS(Seguimiento!$G:$G,Seguimiento!$R:$R,X12,Seguimiento!$A:$A,_xlfn.MAXIFS(Seguimiento!$A:$A,Seguimiento!$R:$R,X12))),P12) -> 0.3 | F12: =IFERROR(SUMIFS(Seguimiento!$H:$H,Seguimiento!$R:$R,X12,Seguimiento!$A:$A,_xlfn.MAXIFS(Seguimiento!$A:$A,Seguimiento!$R:$R,X12)),0) -> 0 | G12: =IFERROR(SUMIFS(Seguimiento!$I:$I,Seguimiento!$R:$R,X12,Seguimiento!$A:$A,_xlfn.MAXIFS(Seguimiento!$A:$A,Seguimiento!$R:$R,X12)),0) -> 0 | H12: =IFERROR(G12/F12,0) -> 0 | I12: =IFERROR(SUMIFS(Seguimiento!$J:$J,Seguimiento!$R:$R,X12,Seguimiento!$A:$A,_xlfn.MAXIFS(Seguimiento!$A:$A,Seguimiento!$R:$R,X12)),0) -> 0 | J12: =IFERROR(I12/G12,0) -> 0 | K12: =IFERROR(SUMIFS(Seguimiento!$K:$K,Seguimiento!$R:$R,X12,Seguimiento!$A:$A,_xlfn.MAXIFS(Seguimiento!$A:$A,Seguimiento!$R:$R,X12)),0) -> 0 | L12: =IFERROR(SUMIFS(Seguimiento!$L:$L,Seguimiento!$R:$R,X12,Seguimiento!$A:$A,_xlfn.MAXIFS(Seguimiento!$A:$A,Seguimiento!$R:$R,X12)),0) -> 0 | M12: =IFERROR(I12/L12,0) -> 0 | N12: =IFERROR(L12/I12,0) -> 0 | O12: Especial IA | P12: 0.3 | Q12: =ROUND(P12*(1-Leyenda!$B$12),2) -> 0.15 | R12: =ROUND(P12*(1+Leyenda!$B$12),2) -> 0.45 | S12: 0.3 | T12: T-011 | U12: =IFERROR(IF(_xlfn.MAXIFS(Seguimiento!$A:$A,Seguimiento!$R:$R,X12)=0,"",_xlfn.MAXIFS(Seguimiento!$A:$A,Seguimiento!$R:$R,X12)),"") -> 46291 | V12: =IF(AND(G12>=Leyenda!$B$13,K12=0),"PAUSAR (≥15 clics sin venta)",IF(AND(E12<=Q12,G12>=20,M12>0.5),"PAUSAR (puja mínima y ACOS>50%)","")) | W12: =IF(LEFT(V12,6)="PAUSAR","Pausar y crear ticket",IF(G12<Leyenda!$B$14,"Esperar (menos de 10 clics)",IF(K12=0,"Sin ventas aún: vigilar",IF(M12<0.3,"Subir 10-25% (máx. "&TEXT(MIN(R12,S12),"0.00")&" €)",IF(M12<=Leyenda!$B$5,"En objetivo: no tocar",IF(M12<=0.5,"Bajar 10-25% (mín. "&TEXT(Q12,"0.00")&" €)","Bajar 25-50% (mín. "&TEXT(Q12,"0.00")&" €)")))))) -> Esperar (menos de 10 clics) | X12: =A12&" | "&C12&" | "&D12 -> Pou - Principal V2 | muñeco pou regalo niño | Frase
A13: Pou - Principal V2 | B13: =IFERROR(INDEX(Seguimiento!$E:$E,MATCH(X13&"#"&_xlfn.MAXIFS(Seguimiento!$A:$A,Seguimiento!$R:$R,X13),Seguimiento!$S:$S,0)),"Activado") -> En pausa | C13: pou peluche | D13: Frase | E13: =IFERROR(IF(_xlfn.MAXIFS(Seguimiento!$A:$A,Seguimiento!$R:$R,X13)=0,P13,SUMIFS(Seguimiento!$G:$G,Seguimiento!$R:$R,X13,Seguimiento!$A:$A,_xlfn.MAXIFS(Seguimiento!$A:$A,Seguimiento!$R:$R,X13))),P13) -> 0.24 | F13: =IFERROR(SUMIFS(Seguimiento!$H:$H,Seguimiento!$R:$R,X13,Seguimiento!$A:$A,_xlfn.MAXIFS(Seguimiento!$A:$A,Seguimiento!$R:$R,X13)),0) -> 0 | G13: =IFERROR(SUMIFS(Seguimiento!$I:$I,Seguimiento!$R:$R,X13,Seguimiento!$A:$A,_xlfn.MAXIFS(Seguimiento!$A:$A,Seguimiento!$R:$R,X13)),0) -> 0 | H13: =IFERROR(G13/F13,0) -> 0 | I13: =IFERROR(SUMIFS(Seguimiento!$J:$J,Seguimiento!$R:$R,X13,Seguimiento!$A:$A,_xlfn.MAXIFS(Seguimiento!$A:$A,Seguimiento!$R:$R,X13)),0) -> 0 | J13: =IFERROR(I13/G13,0) -> 0 | K13: =IFERROR(SUMIFS(Seguimiento!$K:$K,Seguimiento!$R:$R,X13,Seguimiento!$A:$A,_xlfn.MAXIFS(Seguimiento!$A:$A,Seguimiento!$R:$R,X13)),0) -> 0 | L13: =IFERROR(SUMIFS(Seguimiento!$L:$L,Seguimiento!$R:$R,X13,Seguimiento!$A:$A,_xlfn.MAXIFS(Seguimiento!$A:$A,Seguimiento!$R:$R,X13)),0) -> 0 | M13: =IFERROR(I13/L13,0) -> 0 | N13: =IFERROR(L13/I13,0) -> 0 | O13: Especial IA | P13: 0.24 | Q13: =ROUND(P13*(1-Leyenda!$B$12),2) -> 0.12 | R13: =ROUND(P13*(1+Leyenda!$B$12),2) -> 0.36 | S13: 0.24 | T13: T-012 | U13: =IFERROR(IF(_xlfn.MAXIFS(Seguimiento!$A:$A,Seguimiento!$R:$R,X13)=0,"",_xlfn.MAXIFS(Seguimiento!$A:$A,Seguimiento!$R:$R,X13)),"") -> 46291 | V13: =IF(AND(G13>=Leyenda!$B$13,K13=0),"PAUSAR (≥15 clics sin venta)",IF(AND(E13<=Q13,G13>=20,M13>0.5),"PAUSAR (puja mínima y ACOS>50%)","")) | W13: =IF(LEFT(V13,6)="PAUSAR","Pausar y crear ticket",IF(G13<Leyenda!$B$14,"Esperar (menos de 10 clics)",IF(K13=0,"Sin ventas aún: vigilar",IF(M13<0.3,"Subir 10-25% (máx. "&TEXT(MIN(R13,S13),"0.00")&" €)",IF(M13<=Leyenda!$B$5,"En objetivo: no tocar",IF(M13<=0.5,"Bajar 10-25% (mín. "&TEXT(Q13,"0.00")&" €)","Bajar 25-50% (mín. "&TEXT(Q13,"0.00")&" €)")))))) -> Esperar (menos de 10 clics) | X13: =A13&" | "&C13&" | "&D13 -> Pou - Principal V2 | pou peluche | Frase
A14: TOTAL | C14: Pou - Principal V2 | F14: =SUM(F4:F13) -> 0 | G14: =SUM(G4:G13) -> 0 | H14: =IFERROR(G14/F14,0) -> 0 | I14: =SUM(I4:I13) -> 0 | J14: =IFERROR(I14/G14,0) -> 0 | K14: =SUM(K4:K13) -> 0 | L14: =SUM(L4:L13) -> 0 | M14: =IFERROR(I14/L14,0) -> 0 | N14: =IFERROR(L14/I14,0) -> 0

Sheet Seguimiento
A1: Seguimiento — una fila por keyword/ASIN en cada revisión (cada 3 días). Datos ACUMULADOS desde la creación.
A3: Fecha | B3: Campaña | C3: Palabra clave / segmentación | D3: Tipo de coincidencia | E3: Estado | F3: Ticket | G3: Puja (EUR) | H3: Impresiones | I3: Clics | J3: Coste total (EUR) | K3: Compras | L3: Ventas (EUR) | M3: CTR | N3: CPC (EUR) | O3: ACOS | P3: ROAS | Q3: Nota | R3: Clave | S3: Clave+fecha
A4: 46291 | B4: Pou - Principal V2 | C4: peluches de pou | D4: Amplia | E4: En pausa | G4: 0.12 | H4: 0 | I4: 0 | J4: 0 | K4: 0 | L4: 0 | M4: =IF(C4="","",IFERROR(I4/H4,0)) -> 0 | N4: =IF(C4="","",IFERROR(J4/I4,0)) -> 0 | O4: =IF(C4="","",IFERROR(J4/L4,0)) -> 0 | P4: =IF(C4="","",IFERROR(L4/J4,0)) -> 0 | Q4: Día 0: creación (sin datos todavía) | R4: =IF(C4="","",B4&" | "&C4&" | "&D4) -> Pou - Principal V2 | peluches de pou | Amplia | S4: =IF(C4="","",R4&"#"&A4) -> Pou - Principal V2 | peluches de pou | Amplia#46291
A5: 46291 | B5: Pou - Principal V2 | C5: peluche pou | D5: Frase | E5: En pausa | G5: 0.24 | H5: 0 | I5: 0 | J5: 0 | K5: 0 | L5: 0 | M5: =IF(C5="","",IFERROR(I5/H5,0)) -> 0 | N5: =IF(C5="","",IFERROR(J5/I5,0)) -> 0 | O5: =IF(C5="","",IFERROR(J5/L5,0)) -> 0 | P5: =IF(C5="","",IFERROR(L5/J5,0)) -> 0 | Q5: Día 0: creación (sin datos todavía) | R5: =IF(C5="","",B5&" | "&C5&" | "&D5) -> Pou - Principal V2 | peluche pou | Frase | S5: =IF(C5="","",R5&"#"&A5) -> Pou - Principal V2 | peluche pou | Frase#46291
A6: 46291 | B6: Pou - Principal V2 | C6: muñeco pou | D6: Frase | E6: En pausa | G6: 0.29 | H6: 0 | I6: 0 | J6: 0 | K6: 0 | L6: 0 | M6: =IF(C6="","",IFERROR(I6/H6,0)) -> 0 | N6: =IF(C6="","",IFERROR(J6/I6,0)) -> 0 | O6: =IF(C6="","",IFERROR(J6/L6,0)) -> 0 | P6: =IF(C6="","",IFERROR(L6/J6,0)) -> 0 | Q6: Día 0: creación (sin datos todavía) | R6: =IF(C6="","",B6&" | "&C6&" | "&D6) -> Pou - Principal V2 | muñeco pou | Frase | S6: =IF(C6="","",R6&"#"&A6) -> Pou - Principal V2 | muñeco pou | Frase#46291
A7: 46291 | B7: Pou - Principal V2 | C7: muñeco de peluche pou | D7: Frase | E7: En pausa | G7: 0.24 | H7: 0 | I7: 0 | J7: 0 | K7: 0 | L7: 0 | M7: =IF(C7="","",IFERROR(I7/H7,0)) -> 0 | N7: =IF(C7="","",IFERROR(J7/I7,0)) -> 0 | O7: =IF(C7="","",IFERROR(J7/L7,0)) -> 0 | P7: =IF(C7="","",IFERROR(L7/J7,0)) -> 0 | Q7: Día 0: creación (sin datos todavía) | R7: =IF(C7="","",B7&" | "&C7&" | "&D7) -> Pou - Principal V2 | muñeco de peluche pou | Frase | S7: =IF(C7="","",R7&"#"&A7) -> Pou - Principal V2 | muñeco de peluche pou | Frase#46291
A8: 46291 | B8: Pou - Principal V2 | C8: alien pou | D8: Frase | E8: En pausa | G8: 0.29 | H8: 0 | I8: 0 | J8: 0 | K8: 0 | L8: 0 | M8: =IF(C8="","",IFERROR(I8/H8,0)) -> 0 | N8: =IF(C8="","",IFERROR(J8/I8,0)) -> 0 | O8: =IF(C8="","",IFERROR(J8/L8,0)) -> 0 | P8: =IF(C8="","",IFERROR(L8/J8,0)) -> 0 | Q8: Día 0: creación (sin datos todavía) | R8: =IF(C8="","",B8&" | "&C8&" | "&D8) -> Pou - Principal V2 | alien pou | Frase | S8: =IF(C8="","",R8&"#"&A8) -> Pou - Principal V2 | alien pou | Frase#46291
A9: 46291 | B9: Pou - Principal V2 | C9: peluche pou alienígena | D9: Frase | E9: En pausa | G9: 0.24 | H9: 0 | I9: 0 | J9: 0 | K9: 0 | L9: 0 | M9: =IF(C9="","",IFERROR(I9/H9,0)) -> 0 | N9: =IF(C9="","",IFERROR(J9/I9,0)) -> 0 | O9: =IF(C9="","",IFERROR(J9/L9,0)) -> 0 | P9: =IF(C9="","",IFERROR(L9/J9,0)) -> 0 | Q9: Día 0: creación (sin datos todavía) | R9: =IF(C9="","",B9&" | "&C9&" | "&D9) -> Pou - Principal V2 | peluche pou alienígena | Frase | S9: =IF(C9="","",R9&"#"&A9) -> Pou - Principal V2 | peluche pou alienígena | Frase#46291
A10: 46291 | B10: Pou - Principal V2 | C10: peluche pou 22 cm | D10: Frase | E10: En pausa | G10: 0.25 | H10: 0 | I10: 0 | J10: 0 | K10: 0 | L10: 0 | M10: =IF(C10="","",IFERROR(I10/H10,0)) -> 0 | N10: =IF(C10="","",IFERROR(J10/I10,0)) -> 0 | O10: =IF(C10="","",IFERROR(J10/L10,0)) -> 0 | P10: =IF(C10="","",IFERROR(L10/J10,0)) -> 0 | Q10: Día 0: creación (sin datos todavía) | R10: =IF(C10="","",B10&" | "&C10&" | "&D10) -> Pou - Principal V2 | peluche pou 22 cm | Frase | S10: =IF(C10="","",R10&"#"&A10) -> Pou - Principal V2 | peluche pou 22 cm | Frase#46291
A11: 46291 | B11: Pou - Principal V2 | C11: peluche pou regalo | D11: Frase | E11: En pausa | G11: 0.24 | H11: 0 | I11: 0 | J11: 0 | K11: 0 | L11: 0 | M11: =IF(C11="","",IFERROR(I11/H11,0)) -> 0 | N11: =IF(C11="","",IFERROR(J11/I11,0)) -> 0 | O11: =IF(C11="","",IFERROR(J11/L11,0)) -> 0 | P11: =IF(C11="","",IFERROR(L11/J11,0)) -> 0 | Q11: Día 0: creación (sin datos todavía) | R11: =IF(C11="","",B11&" | "&C11&" | "&D11) -> Pou - Principal V2 | peluche pou regalo | Frase | S11: =IF(C11="","",R11&"#"&A11) -> Pou - Principal V2 | peluche pou regalo | Frase#46291
A12: 46291 | B12: Pou - Principal V2 | C12: muñeco pou regalo niño | D12: Frase | E12: En pausa | G12: 0.3 | H12: 0 | I12: 0 | J12: 0 | K12: 0 | L12: 0 | M12: =IF(C12="","",IFERROR(I12/H12,0)) -> 0 | N12: =IF(C12="","",IFERROR(J12/I12,0)) -> 0 | O12: =IF(C12="","",IFERROR(J12/L12,0)) -> 0 | P12: =IF(C12="","",IFERROR(L12/J12,0)) -> 0 | Q12: Día 0: creación (sin datos todavía) | R12: =IF(C12="","",B12&" | "&C12&" | "&D12) -> Pou - Principal V2 | muñeco pou regalo niño | Frase | S12: =IF(C12="","",R12&"#"&A12) -> Pou - Principal V2 | muñeco pou regalo niño | Frase#46291
A13: 46291 | B13: Pou - Principal V2 | C13: pou peluche | D13: Frase | E13: En pausa | G13: 0.24 | H13: 0 | I13: 0 | J13: 0 | K13: 0 | L13: 0 | M13: =IF(C13="","",IFERROR(I13/H13,0)) -> 0 | N13: =IF(C13="","",IFERROR(J13/I13,0)) -> 0 | O13: =IF(C13="","",IFERROR(J13/L13,0)) -> 0 | P13: =IF(C13="","",IFERROR(L13/J13,0)) -> 0 | Q13: Día 0: creación (sin datos todavía) | R13: =IF(C13="","",B13&" | "&C13&" | "&D13) -> Pou - Principal V2 | pou peluche | Frase | S13: =IF(C13="","",R13&"#"&A13) -> Pou - Principal V2 | pou peluche | Frase#46291
M14: =IF(C14="","",IFERROR(I14/H14,0)) | N14: =IF(C14="","",IFERROR(J14/I14,0)) | O14: =IF(C14="","",IFERROR(J14/L14,0)) | P14: =IF(C14="","",IFERROR(L14/J14,0)) | R14: =IF(C14="","",B14&" | "&C14&" | "&D14) | S14: =IF(C14="","",R14&"#"&A14)
M15: =IF(C15="","",IFERROR(I15/H15,0)) | N15: =IF(C15="","",IFERROR(J15/I15,0)) | O15: =IF(C15="","",IFERROR(J15/L15,0)) | P15: =IF(C15="","",IFERROR(L15/J15,0)) | R15: =IF(C15="","",B15&" | "&C15&" | "&D15) | S15: =IF(C15="","",R15&"#"&A15)
M16: =IF(C16="","",IFERROR(I16/H16,0)) | N16: =IF(C16="","",IFERROR(J16/I16,0)) | O16: =IF(C16="","",IFERROR(J16/L16,0)) | P16: =IF(C16="","",IFERROR(L16/J16,0)) | R16: =IF(C16="","",B16&" | "&C16&" | "&D16) | S16: =IF(C16="","",R16&"#"&A16)
M17: =IF(C17="","",IFERROR(I17/H17,0)) | N17: =IF(C17="","",IFERROR(J17/I17,0)) | O17: =IF(C17="","",IFERROR(J17/L17,0)) | P17: =IF(C17="","",IFERROR(L17/J17,0)) | R17: =IF(C17="","",B17&" | "&C17&" | "&D17) | S17: =IF(C17="","",R17&"#"&A17)
M18: =IF(C18="","",IFERROR(I18/H18,0)) | N18: =IF(C18="","",IFERROR(J18/I18,0)) | O18: =IF(C18="","",IFERROR(J18/L18,0)) | P18: =IF(C18="","",IFERROR(L18/J18,0)) | R18: =IF(C18="","",B18&" | "&C18&" | "&D18) | S18: =IF(C18="","",R18&"#"&A18)
M19: =IF(C19="","",IFERROR(I19/H19,0)) | N19: =IF(C19="","",IFERROR(J19/I19,0)) | O19: =IF(C19="","",IFERROR(J19/L19,0)) | P19: =IF(C19="","",IFERROR(L19/J19,0)) | R19: =IF(C19="","",B19&" | "&C19&" | "&D19) | S19: =IF(C19="","",R19&"#"&A19)
M20: =IF(C20="","",IFERROR(I20/H20,0)) | N20: =IF(C20="","",IFERROR(J20/I20,0)) | O20: =IF(C20="","",IFERROR(J20/L20,0)) | P20: =IF(C20="","",IFERROR(L20/J20,0)) | R20: =IF(C20="","",B20&" | "&C20&" | "&D20) | S20: =IF(C20="","",R20&"#"&A20)
M21: =IF(C21="","",IFERROR(I21/H21,0)) | N21: =IF(C21="","",IFERROR(J21/I21,0)) | O21: =IF(C21="","",IFERROR(J21/L21,0)) | P21: =IF(C21="","",IFERROR(L21/J21,0)) | R21: =IF(C21="","",B21&" | "&C21&" | "&D21) | S21: =IF(C21="","",R21&"#"&A21)
M22: =IF(C22="","",IFERROR(I22/H22,0)) | N22: =IF(C22="","",IFERROR(J22/I22,0)) | O22: =IF(C22="","",IFERROR(J22/L22,0)) | P22: =IF(C22="","",IFERROR(L22/J22,0)) | R22: =IF(C22="","",B22&" | "&C22&" | "&D22) | S22: =IF(C22="","",R22&"#"&A22)
M23: =IF(C23="","",IFERROR(I23/H23,0)) | N23: =IF(C23="","",IFERROR(J23/I23,0)) | O23: =IF(C23="","",IFERROR(J23/L23,0)) | P23: =IF(C23="","",IFERROR(L23/J23,0)) | R23: =IF(C23="","",B23&" | "&C23&" | "&D23) | S23: =IF(C23="","",R23&"#"&A23)
M24: =IF(C24="","",IFERROR(I24/H24,0)) | N24: =IF(C24="","",IFERROR(J24/I24,0)) | O24: =IF(C24="","",IFERROR(J24/L24,0)) | P24: =IF(C24="","",IFERROR(L24/J24,0)) | R24: =IF(C24="","",B24&" | "&C24&" | "&D24) | S24: =IF(C24="","",R24&"#"&A24)
M25: =IF(C25="","",IFERROR(I25/H25,0)) | N25: =IF(C25="","",IFERROR(J25/I25,0)) | O25: =IF(C25="","",IFERROR(J25/L25,0)) | P25: =IF(C25="","",IFERROR(L25/J25,0)) | R25: =IF(C25="","",B25&" | "&C25&" | "&D25) | S25: =IF(C25="","",R25&"#"&A25)
... M603: =IF(C603="","",IFERROR(I603/H603,0)) | N603: =IF(C603="","",IFERROR(J603/I603,0)) | O603: =IF(C603="","",IFERROR(J603/L603,0)) | P603: =IF(C603="","",IFERROR(L603/J603,0)) | R603: =IF(C603="","",B603&" | "&C603&" | "&D603) | S603: =IF(C603="","",R603&"#"&A603)

Sheet Tickets
A1: Tickets — uno por cambio. 'Base' = acumulado al aplicar el cambio; 'Después' = solo lo ocurrido desde entonces.
A3: Ticket | B3: Fecha creación | C3: Campaña | D3: Tipo de cambio | E3: Palabra clave / segmentación | F3: Tipo de coincidencia | G3: Valor antes | H3: Valor después | I3: Cambio % | J3: Motivo / hipótesis | K3: ACOS de referencia | L3: Qué es la referencia | M3: Estado del ticket | N3: Fecha aplicado | O3: Revisar a partir de | P3: Base: Clics | Q3: Base: Coste | R3: Base: Compras | S3: Base: Ventas | T3: Después: Clics | U3: Después: Coste | V3: Después: Compras | W3: Después: Ventas | X3: Después: ACOS | Y3: Veredicto | Z3: Cómo se aplica | AA3: Notas
A4: T-001 | B4: 46291 | C4: — | D4: Cambiar cartera | H4: 840 | I4: =IF(OR(G4="",H4="",G4=0),"",H4/G4-1) | J4: Subir el límite MENSUAL de la cartera 'FreshFinder - cartera' a 840 € y meter dentro las campañas nuevas (Pou - Principal V2). | M4: Pendiente de aplicar | O4: =IF(N4="","",N4+Leyenda!$B$15) | P4: 0 | Q4: 0 | R4: 0 | S4: 0 | T4: =IF(OR(E4="",N4=""),"",IFERROR(INDEX(Segmentación!$G$4:$G$13,MATCH(C4&" | "&E4&" | "&F4,Segmentación!$X$4:$X$13,0))-P4,"")) | U4: =IF(OR(E4="",N4=""),"",IFERROR(INDEX(Segmentación!$I$4:$I$13,MATCH(C4&" | "&E4&" | "&F4,Segmentación!$X$4:$X$13,0))-Q4,"")) | V4: =IF(OR(E4="",N4=""),"",IFERROR(INDEX(Segmentación!$K$4:$K$13,MATCH(C4&" | "&E4&" | "&F4,Segmentación!$X$4:$X$13,0))-R4,"")) | W4: =IF(OR(E4="",N4=""),"",IFERROR(INDEX(Segmentación!$L$4:$L$13,MATCH(C4&" | "&E4&" | "&F4,Segmentación!$X$4:$X$13,0))-S4,"")) | X4: =IF(OR(T4="",W4=""),"",IF(W4=0,"",U4/W4)) | Y4: =IF(D4="","",IF(OR(E4="",ISNUMBER(SEARCH("negativa",D4))),IF(N4="","Pendiente de aplicar","Aplicado (no se evalúa)"),IF(N4="","Pendiente de aplicar",IF(T4="","Sin datos",IF(T4<Leyenda!$B$14,"Esperando datos ("&T4&" de 10 clics)",IF(V4=0,"Empeora: "&T4&" clics sin venta",IF(TODAY()<O4,"Esperando atribución (7 días)",IF(X4<=K4,"Mejora (ACOS "&TEXT(X4,"0%")&")","Empeora (ACOS "&TEXT(X4,"0%")&")")))))))) -> Pendiente de aplicar | Z4: A mano
A5: T-002 | B5: 46291 | C5: Pou - Principal V2 | D5: Crear campaña y grupo | H5: 7 | I5: =IF(OR(G5="",H5="",G5=0),"",H5/G5-1) | J5: Campaña 'Pou - Principal V2' (manual, palabras clave, 7 €/día, pujas dinámicas solo reducir) con el grupo 'Pou - Principal V2' y el anuncio B0CPHXXHRQ (NN-8FIP-9ZZT). Se crea en pausa. | M5: Pendiente de aplicar | O5: =IF(N5="","",N5+Leyenda!$B$15) | P5: 0 | Q5: 0 | R5: 0 | S5: 0 | T5: =IF(OR(E5="",N5=""),"",IFERROR(INDEX(Segmentación!$G$4:$G$13,MATCH(C5&" | "&E5&" | "&F5,Segmentación!$X$4:$X$13,0))-P5,"")) | U5: =IF(OR(E5="",N5=""),"",IFERROR(INDEX(Segmentación!$I$4:$I$13,MATCH(C5&" | "&E5&" | "&F5,Segmentación!$X$4:$X$13,0))-Q5,"")) | V5: =IF(OR(E5="",N5=""),"",IFERROR(INDEX(Segmentación!$K$4:$K$13,MATCH(C5&" | "&E5&" | "&F5,Segmentación!$X$4:$X$13,0))-R5,"")) | W5: =IF(OR(E5="",N5=""),"",IFERROR(INDEX(Segmentación!$L$4:$L$13,MATCH(C5&" | "&E5&" | "&F5,Segmentación!$X$4:$X$13,0))-S5,"")) | X5: =IF(OR(T5="",W5=""),"",IF(W5=0,"",U5/W5)) | Y5: =IF(D5="","",IF(OR(E5="",ISNUMBER(SEARCH("negativa",D5))),IF(N5="","Pendiente de aplicar","Aplicado (no se evalúa)"),IF(N5="","Pendiente de aplicar",IF(T5="","Sin datos",IF(T5<Leyenda!$B$14,"Esperando datos ("&T5&" de 10 clics)",IF(V5=0,"Empeora: "&T5&" clics sin venta",IF(TODAY()<O5,"Esperando atribución (7 días)",IF(X5<=K5,"Mejora (ACOS "&TEXT(X5,"0%")&")","Empeora (ACOS "&TEXT(X5,"0%")&")")))))))) -> Pendiente de aplicar | Z5: Hoja masiva
A6: T-003 | B6: 46291 | C6: Pou - Principal V2 | D6: Añadir keyword (histórica) | E6: peluches de pou | F6: Amplia | G6: 0.1 | H6: 0.12 | I6: =IF(OR(G6="",H6="",G6=0),"",H6/G6-1) -> 0.2 | J6: Histórico (suma de 2 grupos): 1 clics, 1 compras, 0.20 € de gasto, 11.99 € de ventas. ACOS 1.7% < 30% → subir 25% (limitada a la puja máx. rentable 0.12 €, con la conversión media del producto porque solo tiene 1 clics). | K6: 0.0167 | L6: ACOS en el histórico | M6: Pendiente de aplicar | O6: =IF(N6="","",N6+Leyenda!$B$15) | P6: 0 | Q6: 0 | R6: 0 | S6: 0 | T6: =IF(OR(E6="",N6=""),"",IFERROR(INDEX(Segmentación!$G$4:$G$13,MATCH(C6&" | "&E6&" | "&F6,Segmentación!$X$4:$X$13,0))-P6,"")) | U6: =IF(OR(E6="",N6=""),"",IFERROR(INDEX(Segmentación!$I$4:$I$13,MATCH(C6&" | "&E6&" | "&F6,Segmentación!$X$4:$X$13,0))-Q6,"")) | V6: =IF(OR(E6="",N6=""),"",IFERROR(INDEX(Segmentación!$K$4:$K$13,MATCH(C6&" | "&E6&" | "&F6,Segmentación!$X$4:$X$13,0))-R6,"")) | W6: =IF(OR(E6="",N6=""),"",IFERROR(INDEX(Segmentación!$L$4:$L$13,MATCH(C6&" | "&E6&" | "&F6,Segmentación!$X$4:$X$13,0))-S6,"")) | X6: =IF(OR(T6="",W6=""),"",IF(W6=0,"",U6/W6)) | Y6: =IF(D6="","",IF(OR(E6="",ISNUMBER(SEARCH("negativa",D6))),IF(N6="","Pendiente de aplicar","Aplicado (no se evalúa)"),IF(N6="","Pendiente de aplicar",IF(T6="","Sin datos",IF(T6<Leyenda!$B$14,"Esperando datos ("&T6&" de 10 clics)",IF(V6=0,"Empeora: "&T6&" clics sin venta",IF(TODAY()<O6,"Esperando atribución (7 días)",IF(X6<=K6,"Mejora (ACOS "&TEXT(X6,"0%")&")","Empeora (ACOS "&TEXT(X6,"0%")&")")))))))) -> Pendiente de aplicar | Z6: Hoja masiva
A7: T-004 | B7: 46291 | C7: Pou - Principal V2 | D7: Añadir keyword (especial IA) | E7: peluche pou | F7: Frase | H7: 0.24 | I7: =IF(OR(G7="",H7="",G7=0),"",H7/G7-1) | J7: La búsqueda principal del producto. Ya existía, pero con puja de 0,09 € casi no salió. Modelo: 5.6% compra/clic → puja máx. rentable 0.24 € (ACOS 35%). | K7: =Leyenda!$B$5 -> 0.35 | L7: ACOS objetivo | M7: Pendiente de aplicar | O7: =IF(N7="","",N7+Leyenda!$B$15) | P7: 0 | Q7: 0 | R7: 0 | S7: 0 | T7: =IF(OR(E7="",N7=""),"",IFERROR(INDEX(Segmentación!$G$4:$G$13,MATCH(C7&" | "&E7&" | "&F7,Segmentación!$X$4:$X$13,0))-P7,"")) | U7: =IF(OR(E7="",N7=""),"",IFERROR(INDEX(Segmentación!$I$4:$I$13,MATCH(C7&" | "&E7&" | "&F7,Segmentación!$X$4:$X$13,0))-Q7,"")) | V7: =IF(OR(E7="",N7=""),"",IFERROR(INDEX(Segmentación!$K$4:$K$13,MATCH(C7&" | "&E7&" | "&F7,Segmentación!$X$4:$X$13,0))-R7,"")) | W7: =IF(OR(E7="",N7=""),"",IFERROR(INDEX(Segmentación!$L$4:$L$13,MATCH(C7&" | "&E7&" | "&F7,Segmentación!$X$4:$X$13,0))-S7,"")) | X7: =IF(OR(T7="",W7=""),"",IF(W7=0,"",U7/W7)) | Y7: =IF(D7="","",IF(OR(E7="",ISNUMBER(SEARCH("negativa",D7))),IF(N7="","Pendiente de aplicar","Aplicado (no se evalúa)"),IF(N7="","Pendiente de aplicar",IF(T7="","Sin datos",IF(T7<Leyenda!$B$14,"Esperando datos ("&T7&" de 10 clics)",IF(V7=0,"Empeora: "&T7&" clics sin venta",IF(TODAY()<O7,"Esperando atribución (7 días)",IF(X7<=K7,"Mejora (ACOS "&TEXT(X7,"0%")&")","Empeora (ACOS "&TEXT(X7,"0%")&")")))))))) -> Pendiente de aplicar | Z7: Hoja masiva
A8: T-005 | B8: 46291 | C8: Pou - Principal V2 | D8: Añadir keyword (especial IA) | E8: muñeco pou | F8: Frase | H8: 0.29 | I8: =IF(OR(G8="",H8="",G8=0),"",H8/G8-1) | J8: Sinónimo de peluche que usa el título ('Muñeco de peluche Pou'). Modelo: 6.9% compra/clic → puja máx. rentable 0.29 € (ACOS 35%). | K8: =Leyenda!$B$5 -> 0.35 | L8: ACOS objetivo | M8: Pendiente de aplicar | O8: =IF(N8="","",N8+Leyenda!$B$15) | P8: 0 | Q8: 0 | R8: 0 | S8: 0 | T8: =IF(OR(E8="",N8=""),"",IFERROR(INDEX(Segmentación!$G$4:$G$13,MATCH(C8&" | "&E8&" | "&F8,Segmentación!$X$4:$X$13,0))-P8,"")) | U8: =IF(OR(E8="",N8=""),"",IFERROR(INDEX(Segmentación!$I$4:$I$13,MATCH(C8&" | "&E8&" | "&F8,Segmentación!$X$4:$X$13,0))-Q8,"")) | V8: =IF(OR(E8="",N8=""),"",IFERROR(INDEX(Segmentación!$K$4:$K$13,MATCH(C8&" | "&E8&" | "&F8,Segmentación!$X$4:$X$13,0))-R8,"")) | W8: =IF(OR(E8="",N8=""),"",IFERROR(INDEX(Segmentación!$L$4:$L$13,MATCH(C8&" | "&E8&" | "&F8,Segmentación!$X$4:$X$13,0))-S8,"")) | X8: =IF(OR(T8="",W8=""),"",IF(W8=0,"",U8/W8)) | Y8: =IF(D8="","",IF(OR(E8="",ISNUMBER(SEARCH("negativa",D8))),IF(N8="","Pendiente de aplicar","Aplicado (no se evalúa)"),IF(N8="","Pendiente de aplicar",IF(T8="","Sin datos",IF(T8<Leyenda!$B$14,"Esperando datos ("&T8&" de 10 clics)",IF(V8=0,"Empeora: "&T8&" clics sin venta",IF(TODAY()<O8,"Esperando atribución (7 días)",IF(X8<=K8,"Mejora (ACOS "&TEXT(X8,"0%")&")","Empeora (ACOS "&TEXT(X8,"0%")&")")))))))) -> Pendiente de aplicar | Z8: Hoja masiva
A9: T-006 | B9: 46291 | C9: Pou - Principal V2 | D9: Añadir keyword (especial IA) | E9: muñeco de peluche pou | F9: Frase | H9: 0.24 | I9: =IF(OR(G9="",H9="",G9=0),"",H9/G9-1) | J9: El nombre exacto del título. Modelo: 5.7% compra/clic → puja máx. rentable 0.24 € (ACOS 35%). | K9: =Leyenda!$B$5 -> 0.35 | L9: ACOS objetivo | M9: Pendiente de aplicar | O9: =IF(N9="","",N9+Leyenda!$B$15) | P9: 0 | Q9: 0 | R9: 0 | S9: 0 | T9: =IF(OR(E9="",N9=""),"",IFERROR(INDEX(Segmentación!$G$4:$G$13,MATCH(C9&" | "&E9&" | "&F9,Segmentación!$X$4:$X$13,0))-P9,"")) | U9: =IF(OR(E9="",N9=""),"",IFERROR(INDEX(Segmentación!$I$4:$I$13,MATCH(C9&" | "&E9&" | "&F9,Segmentación!$X$4:$X$13,0))-Q9,"")) | V9: =IF(OR(E9="",N9=""),"",IFERROR(INDEX(Segmentación!$K$4:$K$13,MATCH(C9&" | "&E9&" | "&F9,Segmentación!$X$4:$X$13,0))-R9,"")) | W9: =IF(OR(E9="",N9=""),"",IFERROR(INDEX(Segmentación!$L$4:$L$13,MATCH(C9&" | "&E9&" | "&F9,Segmentación!$X$4:$X$13,0))-S9,"")) | X9: =IF(OR(T9="",W9=""),"",IF(W9=0,"",U9/W9)) | Y9: =IF(D9="","",IF(OR(E9="",ISNUMBER(SEARCH("negativa",D9))),IF(N9="","Pendiente de aplicar","Aplicado (no se evalúa)"),IF(N9="","Pendiente de aplicar",IF(T9="","Sin datos",IF(T9<Leyenda!$B$14,"Esperando datos ("&T9&" de 10 clics)",IF(V9=0,"Empeora: "&T9&" clics sin venta",IF(TODAY()<O9,"Esperando atribución (7 días)",IF(X9<=K9,"Mejora (ACOS "&TEXT(X9,"0%")&")","Empeora (ACOS "&TEXT(X9,"0%")&")")))))))) -> Pendiente de aplicar | Z9: Hoja masiva
A10: T-007 | B10: 46291 | C10: Pou - Principal V2 | D10: Añadir keyword (especial IA) | E10: alien pou | F10: Frase | H10: 0.29 | I10: =IF(OR(G10="",H10="",G10=0),"",H10/G10-1) | J10: Cómo busca mucha gente este peluche (ya estaba entre sus keywords, sin apenas pujas). Modelo: 6.9% compra/clic → puja máx. rentable 0.29 € (ACOS 35%). | K10: =Leyenda!$B$5 -> 0.35 | L10: ACOS objetivo | M10: Pendiente de aplicar | O10: =IF(N10="","",N10+Leyenda!$B$15) | P10: 0 | Q10: 0 | R10: 0 | S10: 0 | T10: =IF(OR(E10="",N10=""),"",IFERROR(INDEX(Segmentación!$G$4:$G$13,MATCH(C10&" | "&E10&" | "&F10,Segmentación!$X$4:$X$13,0))-P10,"")) | U10: =IF(OR(E10="",N10=""),"",IFERROR(INDEX(Segmentación!$I$4:$I$13,MATCH(C10&" | "&E10&" | "&F10,Segmentación!$X$4:$X$13,0))-Q10,"")) | V10: =IF(OR(E10="",N10=""),"",IFERROR(INDEX(Segmentación!$K$4:$K$13,MATCH(C10&" | "&E10&" | "&F10,Segmentación!$X$4:$X$13,0))-R10,"")) | W10: =IF(OR(E10="",N10=""),"",IFERROR(INDEX(Segmentación!$L$4:$L$13,MATCH(C10&" | "&E10&" | "&F10,Segmentación!$X$4:$X$13,0))-S10,"")) | X10: =IF(OR(T10="",W10=""),"",IF(W10=0,"",U10/W10)) | Y10: =IF(D10="","",IF(OR(E10="",ISNUMBER(SEARCH("negativa",D10))),IF(N10="","Pendiente de aplicar","Aplicado (no se evalúa)"),IF(N10="","Pendiente de aplicar",IF(T10="","Sin datos",IF(T10<Leyenda!$B$14,"Esperando datos ("&T10&" de 10 clics)",IF(V10=0,"Empeora: "&T10&" clics sin venta",IF(TODAY()<O10,"Esperando atribución (7 días)",IF(X10<=K10,"Mejora (ACOS "&TEXT(X10,"0%")&")","Empeora (ACOS "&TEXT(X10,"0%")&")")))))))) -> Pendiente de aplicar | Z10: Hoja masiva
A11: T-008 | B11: 46291 | C11: Pou - Principal V2 | D11: Añadir keyword (especial IA) | E11: peluche pou alienígena | F11: Frase | H11: 0.24 | I11: =IF(OR(G11="",H11="",G11=0),"",H11/G11-1) | J11: Palabra del título: 'alienígena con expresión'. Modelo: 5.7% compra/clic → puja máx. rentable 0.24 € (ACOS 35%). | K11: =Leyenda!$B$5 -> 0.35 | L11: ACOS objetivo | M11: Pendiente de aplicar | O11: =IF(N11="","",N11+Leyenda!$B$15) | P11: 0 | Q11: 0 | R11: 0 | S11: 0 | T11: =IF(OR(E11="",N11=""),"",IFERROR(INDEX(Segmentación!$G$4:$G$13,MATCH(C11&" | "&E11&" | "&F11,Segmentación!$X$4:$X$13,0))-P11,"")) | U11: =IF(OR(E11="",N11=""),"",IFERROR(INDEX(Segmentación!$I$4:$I$13,MATCH(C11&" | "&E11&" | "&F11,Segmentación!$X$4:$X$13,0))-Q11,"")) | V11: =IF(OR(E11="",N11=""),"",IFERROR(INDEX(Segmentación!$K$4:$K$13,MATCH(C11&" | "&E11&" | "&F11,Segmentación!$X$4:$X$13,0))-R11,"")) | W11: =IF(OR(E11="",N11=""),"",IFERROR(INDEX(Segmentación!$L$4:$L$13,MATCH(C11&" | "&E11&" | "&F11,Segmentación!$X$4:$X$13,0))-S11,"")) | X11: =IF(OR(T11="",W11=""),"",IF(W11=0,"",U11/W11)) | Y11: =IF(D11="","",IF(OR(E11="",ISNUMBER(SEARCH("negativa",D11))),IF(N11="","Pendiente de aplicar","Aplicado (no se evalúa)"),IF(N11="","Pendiente de aplicar",IF(T11="","Sin datos",IF(T11<Leyenda!$B$14,"Esperando datos ("&T11&" de 10 clics)",IF(V11=0,"Empeora: "&T11&" clics sin venta",IF(TODAY()<O11,"Esperando atribución (7 días)",IF(X11<=K11,"Mejora (ACOS "&TEXT(X11,"0%")&")","Empeora (ACOS "&TEXT(X11,"0%")&")")))))))) -> Pendiente de aplicar | Z11: Hoja masiva
A12: T-009 | B12: 46291 | C12: Pou - Principal V2 | D12: Añadir keyword (especial IA) | E12: peluche pou 22 cm | F12: Frase | H12: 0.25 | I12: =IF(OR(G12="",H12="",G12=0),"",H12/G12-1) | J12: Quien busca el tamaño sabe lo que quiere: intención de compra alta. Modelo: 5.9% compra/clic → puja máx. rentable 0.25 € (ACOS 35%). | K12: =Leyenda!$B$5 -> 0.35 | L12: ACOS objetivo | M12: Pendiente de aplicar | O12: =IF(N12="","",N12+Leyenda!$B$15) | P12: 0 | Q12: 0 | R12: 0 | S12: 0 | T12: =IF(OR(E12="",N12=""),"",IFERROR(INDEX(Segmentación!$G$4:$G$13,MATCH(C12&" | "&E12&" | "&F12,Segmentación!$X$4:$X$13,0))-P12,"")) | U12: =IF(OR(E12="",N12=""),"",IFERROR(INDEX(Segmentación!$I$4:$I$13,MATCH(C12&" | "&E12&" | "&F12,Segmentación!$X$4:$X$13,0))-Q12,"")) | V12: =IF(OR(E12="",N12=""),"",IFERROR(INDEX(Segmentación!$K$4:$K$13,MATCH(C12&" | "&E12&" | "&F12,Segmentación!$X$4:$X$13,0))-R12,"")) | W12: =IF(OR(E12="",N12=""),"",IFERROR(INDEX(Segmentación!$L$4:$L$13,MATCH(C12&" | "&E12&" | "&F12,Segmentación!$X$4:$X$13,0))-S12,"")) | X12: =IF(OR(T12="",W12=""),"",IF(W12=0,"",U12/W12)) | Y12: =IF(D12="","",IF(OR(E12="",ISNUMBER(SEARCH("negativa",D12))),IF(N12="","Pendiente de aplicar","Aplicado (no se evalúa)"),IF(N12="","Pendiente de aplicar",IF(T12="","Sin datos",IF(T12<Leyenda!$B$14,"Esperando datos ("&T12&" de 10 clics)",IF(V12=0,"Empeora: "&T12&" clics sin venta",IF(TODAY()<O12,"Esperando atribución (7 días)",IF(X12<=K12,"Mejora (ACOS "&TEXT(X12,"0%")&")","Empeora (ACOS "&TEXT(X12,"0%")&")")))))))) -> Pendiente de aplicar | Z12: Hoja masiva
A13: T-010 | B13: 46291 | C13: Pou - Principal V2 | D13: Añadir keyword (especial IA) | E13: peluche pou regalo | F13: Frase | H13: 0.24 | I13: =IF(OR(G13="",H13="",G13=0),"",H13/G13-1) | J13: El título lo vende como regalo. Modelo: 5.7% compra/clic → puja máx. rentable 0.24 € (ACOS 35%). | K13: =Leyenda!$B$5 -> 0.35 | L13: ACOS objetivo | M13: Pendiente de aplicar | O13: =IF(N13="","",N13+Leyenda!$B$15) | P13: 0 | Q13: 0 | R13: 0 | S13: 0 | T13: =IF(OR(E13="",N13=""),"",IFERROR(INDEX(Segmentación!$G$4:$G$13,MATCH(C13&" | "&E13&" | "&F13,Segmentación!$X$4:$X$13,0))-P13,"")) | U13: =IF(OR(E13="",N13=""),"",IFERROR(INDEX(Segmentación!$I$4:$I$13,MATCH(C13&" | "&E13&" | "&F13,Segmentación!$X$4:$X$13,0))-Q13,"")) | V13: =IF(OR(E13="",N13=""),"",IFERROR(INDEX(Segmentación!$K$4:$K$13,MATCH(C13&" | "&E13&" | "&F13,Segmentación!$X$4:$X$13,0))-R13,"")) | W13: =IF(OR(E13="",N13=""),"",IFERROR(INDEX(Segmentación!$L$4:$L$13,MATCH(C13&" | "&E13&" | "&F13,Segmentación!$X$4:$X$13,0))-S13,"")) | X13: =IF(OR(T13="",W13=""),"",IF(W13=0,"",U13/W13)) | Y13: =IF(D13="","",IF(OR(E13="",ISNUMBER(SEARCH("negativa",D13))),IF(N13="","Pendiente de aplicar","Aplicado (no se evalúa)"),IF(N13="","Pendiente de aplicar",IF(T13="","Sin datos",IF(T13<Leyenda!$B$14,"Esperando datos ("&T13&" de 10 clics)",IF(V13=0,"Empeora: "&T13&" clics sin venta",IF(TODAY()<O13,"Esperando atribución (7 días)",IF(X13<=K13,"Mejora (ACOS "&TEXT(X13,"0%")&")","Empeora (ACOS "&TEXT(X13,"0%")&")")))))))) -> Pendiente de aplicar | Z13: Hoja masiva
A14: T-011 | B14: 46291 | C14: Pou - Principal V2 | D14: Añadir keyword (especial IA) | E14: muñeco pou regalo niño | F14: Frase | H14: 0.3 | I14: =IF(OR(G14="",H14="",G14=0),"",H14/G14-1) | J14: 'Regalo para el día del niño' del título. Modelo: 7.3% compra/clic → puja máx. rentable 0.30 € (ACOS 35%). | K14: =Leyenda!$B$5 -> 0.35 | L14: ACOS objetivo | M14: Pendiente de aplicar | O14: =IF(N14="","",N14+Leyenda!$B$15) | P14: 0 | Q14: 0 | R14: 0 | S14: 0 | T14: =IF(OR(E14="",N14=""),"",IFERROR(INDEX(Segmentación!$G$4:$G$13,MATCH(C14&" | "&E14&" | "&F14,Segmentación!$X$4:$X$13,0))-P14,"")) | U14: =IF(OR(E14="",N14=""),"",IFERROR(INDEX(Segmentación!$I$4:$I$13,MATCH(C14&" | "&E14&" | "&F14,Segmentación!$X$4:$X$13,0))-Q14,"")) | V14: =IF(OR(E14="",N14=""),"",IFERROR(INDEX(Segmentación!$K$4:$K$13,MATCH(C14&" | "&E14&" | "&F14,Segmentación!$X$4:$X$13,0))-R14,"")) | W14: =IF(OR(E14="",N14=""),"",IFERROR(INDEX(Segmentación!$L$4:$L$13,MATCH(C14&" | "&E14&" | "&F14,Segmentación!$X$4:$X$13,0))-S14,"")) | X14: =IF(OR(T14="",W14=""),"",IF(W14=0,"",U14/W14)) | Y14: =IF(D14="","",IF(OR(E14="",ISNUMBER(SEARCH("negativa",D14))),IF(N14="","Pendiente de aplicar","Aplicado (no se evalúa)"),IF(N14="","Pendiente de aplicar",IF(T14="","Sin datos",IF(T14<Leyenda!$B$14,"Esperando datos ("&T14&" de 10 clics)",IF(V14=0,"Empeora: "&T14&" clics sin venta",IF(TODAY()<O14,"Esperando atribución (7 días)",IF(X14<=K14,"Mejora (ACOS "&TEXT(X14,"0%")&")","Empeora (ACOS "&TEXT(X14,"0%")&")")))))))) -> Pendiente de aplicar | Z14: Hoja masiva
A15: T-012 | B15: 46291 | C15: Pou - Principal V2 | D15: Añadir keyword (especial IA) | E15: pou peluche | F15: Frase | H15: 0.24 | I15: =IF(OR(G15="",H15="",G15=0),"",H15/G15-1) | J15: Orden inverso de la búsqueda principal (Frase no cubre el cambio de orden). Modelo: 5.6% compra/clic → puja máx. rentable 0.24 € (ACOS 35%). | K15: =Leyenda!$B$5 -> 0.35 | L15: ACOS objetivo | M15: Pendiente de aplicar | O15: =IF(N15="","",N15+Leyenda!$B$15) | P15: 0 | Q15: 0 | R15: 0 | S15: 0 | T15: =IF(OR(E15="",N15=""),"",IFERROR(INDEX(Segmentación!$G$4:$G$13,MATCH(C15&" | "&E15&" | "&F15,Segmentación!$X$4:$X$13,0))-P15,"")) | U15: =IF(OR(E15="",N15=""),"",IFERROR(INDEX(Segmentación!$I$4:$I$13,MATCH(C15&" | "&E15&" | "&F15,Segmentación!$X$4:$X$13,0))-Q15,"")) | V15: =IF(OR(E15="",N15=""),"",IFERROR(INDEX(Segmentación!$K$4:$K$13,MATCH(C15&" | "&E15&" | "&F15,Segmentación!$X$4:$X$13,0))-R15,"")) | W15: =IF(OR(E15="",N15=""),"",IFERROR(INDEX(Segmentación!$L$4:$L$13,MATCH(C15&" | "&E15&" | "&F15,Segmentación!$X$4:$X$13,0))-S15,"")) | X15: =IF(OR(T15="",W15=""),"",IF(W15=0,"",U15/W15)) | Y15: =IF(D15="","",IF(OR(E15="",ISNUMBER(SEARCH("negativa",D15))),IF(N15="","Pendiente de aplicar","Aplicado (no se evalúa)"),IF(N15="","Pendiente de aplicar",IF(T15="","Sin datos",IF(T15<Leyenda!$B$14,"Esperando datos ("&T15&" de 10 clics)",IF(V15=0,"Empeora: "&T15&" clics sin venta",IF(TODAY()<O15,"Esperando atribución (7 días)",IF(X15<=K15,"Mejora (ACOS "&TEXT(X15,"0%")&")","Empeora (ACOS "&TEXT(X15,"0%")&")")))))))) -> Pendiente de aplicar | Z15: Hoja masiva
A16: T-013 | B16: 46291 | C16: Pou - Principal V2 | D16: Añadir negativa | E16: peluche | F16: Exacta negativa | I16: =IF(OR(G16="",H16="",G16=0),"",H16/G16-1) | J16: Búsqueda genérica: 32 clics y 0 ventas en el histórico. Negativa EXACTA: no bloquea 'peluche pou'. | M16: Pendiente de aplicar | O16: =IF(N16="","",N16+Leyenda!$B$15) | P16: 0 | Q16: 0 | R16: 0 | S16: 0 | T16: =IF(OR(E16="",N16=""),"",IFERROR(INDEX(Segmentación!$G$4:$G$13,MATCH(C16&" | "&E16&" | "&F16,Segmentación!$X$4:$X$13,0))-P16,"")) | U16: =IF(OR(E16="",N16=""),"",IFERROR(INDEX(Segmentación!$I$4:$I$13,MATCH(C16&" | "&E16&" | "&F16,Segmentación!$X$4:$X$13,0))-Q16,"")) | V16: =IF(OR(E16="",N16=""),"",IFERROR(INDEX(Segmentación!$K$4:$K$13,MATCH(C16&" | "&E16&" | "&F16,Segmentación!$X$4:$X$13,0))-R16,"")) | W16: =IF(OR(E16="",N16=""),"",IFERROR(INDEX(Segmentación!$L$4:$L$13,MATCH(C16&" | "&E16&" | "&F16,Segmentación!$X$4:$X$13,0))-S16,"")) | X16: =IF(OR(T16="",W16=""),"",IF(W16=0,"",U16/W16)) | Y16: =IF(D16="","",IF(OR(E16="",ISNUMBER(SEARCH("negativa",D16))),IF(N16="","Pendiente de aplicar","Aplicado (no se evalúa)"),IF(N16="","Pendiente de aplicar",IF(T16="","Sin datos",IF(T16<Leyenda!$B$14,"Esperando datos ("&T16&" de 10 clics)",IF(V16=0,"Empeora: "&T16&" clics sin venta",IF(TODAY()<O16,"Esperando atribución (7 días)",IF(X16<=K16,"Mejora (ACOS "&TEXT(X16,"0%")&")","Empeora (ACOS "&TEXT(X16,"0%")&")")))))))) -> Pendiente de aplicar | Z16: A mano
A17: T-014 | B17: 46291 | C17: Pou - Principal V2 | D17: Añadir negativa | E17: peluches | F17: Exacta negativa | I17: =IF(OR(G17="",H17="",G17=0),"",H17/G17-1) | J17: Búsqueda genérica, misma razón. | M17: Pendiente de aplicar | O17: =IF(N17="","",N17+Leyenda!$B$15) | P17: 0 | Q17: 0 | R17: 0 | S17: 0 | T17: =IF(OR(E17="",N17=""),"",IFERROR(INDEX(Segmentación!$G$4:$G$13,MATCH(C17&" | "&E17&" | "&F17,Segmentación!$X$4:$X$13,0))-P17,"")) | U17: =IF(OR(E17="",N17=""),"",IFERROR(INDEX(Segmentación!$I$4:$I$13,MATCH(C17&" | "&E17&" | "&F17,Segmentación!$X$4:$X$13,0))-Q17,"")) | V17: =IF(OR(E17="",N17=""),"",IFERROR(INDEX(Segmentación!$K$4:$K$13,MATCH(C17&" | "&E17&" | "&F17,Segmentación!$X$4:$X$13,0))-R17,"")) | W17: =IF(OR(E17="",N17=""),"",IFERROR(INDEX(Segmentación!$L$4:$L$13,MATCH(C17&" | "&E17&" | "&F17,Segmentación!$X$4:$X$13,0))-S17,"")) | X17: =IF(OR(T17="",W17=""),"",IF(W17=0,"",U17/W17)) | Y17: =IF(D17="","",IF(OR(E17="",ISNUMBER(SEARCH("negativa",D17))),IF(N17="","Pendiente de aplicar","Aplicado (no se evalúa)"),IF(N17="","Pendiente de aplicar",IF(T17="","Sin datos",IF(T17<Leyenda!$B$14,"Esperando datos ("&T17&" de 10 clics)",IF(V17=0,"Empeora: "&T17&" clics sin venta",IF(TODAY()<O17,"Esperando atribución (7 días)",IF(X17<=K17,"Mejora (ACOS "&TEXT(X17,"0%")&")","Empeora (ACOS "&TEXT(X17,"0%")&")")))))))) -> Pendiente de aplicar | Z17: A mano
A18: T-015 | I18: =IF(OR(G18="",H18="",G18=0),"",H18/G18-1) | O18: =IF(N18="","",N18+Leyenda!$B$15) | T18: =IF(OR(E18="",N18=""),"",IFERROR(INDEX(Segmentación!$G$4:$G$13,MATCH(C18&" | "&E18&" | "&F18,Segmentación!$X$4:$X$13,0))-P18,"")) | U18: =IF(OR(E18="",N18=""),"",IFERROR(INDEX(Segmentación!$I$4:$I$13,MATCH(C18&" | "&E18&" | "&F18,Segmentación!$X$4:$X$13,0))-Q18,"")) | V18: =IF(OR(E18="",N18=""),"",IFERROR(INDEX(Segmentación!$K$4:$K$13,MATCH(C18&" | "&E18&" | "&F18,Segmentación!$X$4:$X$13,0))-R18,"")) | W18: =IF(OR(E18="",N18=""),"",IFERROR(INDEX(Segmentación!$L$4:$L$13,MATCH(C18&" | "&E18&" | "&F18,Segmentación!$X$4:$X$13,0))-S18,"")) | X18: =IF(OR(T18="",W18=""),"",IF(W18=0,"",U18/W18)) | Y18: =IF(D18="","",IF(OR(E18="",ISNUMBER(SEARCH("negativa",D18))),IF(N18="","Pendiente de aplicar","Aplicado (no se evalúa)"),IF(N18="","Pendiente de aplicar",IF(T18="","Sin datos",IF(T18<Leyenda!$B$14,"Esperando datos ("&T18&" de 10 clics)",IF(V18=0,"Empeora: "&T18&" clics sin venta",IF(TODAY()<O18,"Esperando atribución (7 días)",IF(X18<=K18,"Mejora (ACOS "&TEXT(X18,"0%")&")","Empeora (ACOS "&TEXT(X18,"0%")&")"))))))))
A19: T-016 | I19: =IF(OR(G19="",H19="",G19=0),"",H19/G19-1) | O19: =IF(N19="","",N19+Leyenda!$B$15) | T19: =IF(OR(E19="",N19=""),"",IFERROR(INDEX(Segmentación!$G$4:$G$13,MATCH(C19&" | "&E19&" | "&F19,Segmentación!$X$4:$X$13,0))-P19,"")) | U19: =IF(OR(E19="",N19=""),"",IFERROR(INDEX(Segmentación!$I$4:$I$13,MATCH(C19&" | "&E19&" | "&F19,Segmentación!$X$4:$X$13,0))-Q19,"")) | V19: =IF(OR(E19="",N19=""),"",IFERROR(INDEX(Segmentación!$K$4:$K$13,MATCH(C19&" | "&E19&" | "&F19,Segmentación!$X$4:$X$13,0))-R19,"")) | W19: =IF(OR(E19="",N19=""),"",IFERROR(INDEX(Segmentación!$L$4:$L$13,MATCH(C19&" | "&E19&" | "&F19,Segmentación!$X$4:$X$13,0))-S19,"")) | X19: =IF(OR(T19="",W19=""),"",IF(W19=0,"",U19/W19)) | Y19: =IF(D19="","",IF(OR(E19="",ISNUMBER(SEARCH("negativa",D19))),IF(N19="","Pendiente de aplicar","Aplicado (no se evalúa)"),IF(N19="","Pendiente de aplicar",IF(T19="","Sin datos",IF(T19<Leyenda!$B$14,"Esperando datos ("&T19&" de 10 clics)",IF(V19=0,"Empeora: "&T19&" clics sin venta",IF(TODAY()<O19,"Esperando atribución (7 días)",IF(X19<=K19,"Mejora (ACOS "&TEXT(X19,"0%")&")","Empeora (ACOS "&TEXT(X19,"0%")&")"))))))))
A20: T-017 | I20: =IF(OR(G20="",H20="",G20=0),"",H20/G20-1) | O20: =IF(N20="","",N20+Leyenda!$B$15) | T20: =IF(OR(E20="",N20=""),"",IFERROR(INDEX(Segmentación!$G$4:$G$13,MATCH(C20&" | "&E20&" | "&F20,Segmentación!$X$4:$X$13,0))-P20,"")) | U20: =IF(OR(E20="",N20=""),"",IFERROR(INDEX(Segmentación!$I$4:$I$13,MATCH(C20&" | "&E20&" | "&F20,Segmentación!$X$4:$X$13,0))-Q20,"")) | V20: =IF(OR(E20="",N20=""),"",IFERROR(INDEX(Segmentación!$K$4:$K$13,MATCH(C20&" | "&E20&" | "&F20,Segmentación!$X$4:$X$13,0))-R20,"")) | W20: =IF(OR(E20="",N20=""),"",IFERROR(INDEX(Segmentación!$L$4:$L$13,MATCH(C20&" | "&E20&" | "&F20,Segmentación!$X$4:$X$13,0))-S20,"")) | X20: =IF(OR(T20="",W20=""),"",IF(W20=0,"",U20/W20)) | Y20: =IF(D20="","",IF(OR(E20="",ISNUMBER(SEARCH("negativa",D20))),IF(N20="","Pendiente de aplicar","Aplicado (no se evalúa)"),IF(N20="","Pendiente de aplicar",IF(T20="","Sin datos",IF(T20<Leyenda!$B$14,"Esperando datos ("&T20&" de 10 clics)",IF(V20=0,"Empeora: "&T20&" clics sin venta",IF(TODAY()<O20,"Esperando atribución (7 días)",IF(X20<=K20,"Mejora (ACOS "&TEXT(X20,"0%")&")","Empeora (ACOS "&TEXT(X20,"0%")&")"))))))))
